Workbook

Sheet TABELA
A1: RESULTADOS OFICIAIS - PARTICIPANTES (PONTUAÇÃO)
D3: OFICIAL | I3: COLOCAÇÃO | J3: Nº TABELA | K3: PARTICIPANTE | L3: Pontuação total
A4: 46201 | B4: 0.66666667 | C4: Africa do Sul | D4: 0 | E4: x | F4: 1 | G4: Canadá | H4: A | I4: 1º | J4: 1 | K4: Felipe Barros | L4: ='T (1)'!K111 -> 11
A5: 46202 | B5: 0.58333333 | C5: Brasil | D5: 2 | E5: x | F5: 1 | G5: Japão | I5: 2º | J5: 2 | K5: Erick Maia | L5: ='T (2)'!K111 -> 11
A6: 46202 | B6: 0.72916667 | C6: Alemanha | D6: 1 | E6: x | F6: 1 | G6: Paraguai | I6: 3º | J6: 3 | K6: Ana Beatriz | L6: ='T (3)'!K111 -> 23
A7: 46202 | B7: 0.91666667 | C7: Holanda | D7: 1 | E7: x | F7: 1 | G7: Marrocos | I7: 4º | J7: 4 | K7: André Siqueira | L7: ='T (4)'!K111 -> 16
A8: 46203 | B8: 0.58333333 | C8: Cost. do Marf. | D8: n | E8: x | F8: d | G8: Noruega | I8: 5º | J8: 5 | K8: Nelson Mota | L8: ='T (5)'!K111 -> 14
A9: 46203 | B9: 0.75 | C9: França | D9: n | E9: x | F9: d | G9: Suécia | I9: 6º | J9: 6 | K9: Marco Túlio | L9: ='T (6)'!K111 -> 14
I10: 7º | J10: 7 | K10: Rogério Siqueira | L10: ='T (7)'!K111 -> 18
A11: 46203 | B11: 0.91666667 | C11: México | D11: n | E11: x | F11: d | G11: Equador | H11: B | I11: 8º | J11: 8 | K11: Andrea Mariz | L11: ='T (8)'!K111 -> 18
A12: 46204 | B12: 0.54166667 | C12: Inglaterra | D12: n | E12: x | F12: d | G12: Congo | I12: 9º | J12: 9 | K12: Verônica Bezerra | L12: ='T (9)'!K111 -> 13
A13: 46204 | B13: 0.70833333 | C13: Bélgica | D13: n | E13: x | F13: d | G13: Senegal | I13: 10º | J13: 10 | K13: Alberto Chocrón | L13: ='T (10)'!K111 -> 18
A14: 46204 | B14: 0.875 | C14: Estados Unidos | D14: n | E14: x | F14: d | G14: Bósnia | I14: 11º | J14: 11 | K14: Marco Holder | L14: ='T (11)'!K111 -> 16
A15: 46205 | B15: 0.66666667 | C15: Espanha | D15: n | E15: x | F15: d | G15: Áustria | I15: 12º | J15: 12 | K15: Norivaldo Júnior | L15: ='T (12)'!K111 -> 17
A16: 46205 | B16: 0.83333333 | C16: Portugal | D16: n | E16: x | F16: d | G16: Croácia | I16: 13º | J16: 13 | K16: Marco Aurélio | L16: ='T (13)'!K111 -> 20
I17: 14º | J17: 14 | K17: Gustavo Torres | L17: ='T (14)'!K111 -> 21
A18: 46206 | B18: 0 | C18: Suíça | D18: n | E18: x | F18: d | G18: Argélia | H18: C | I18: 15º | J18: 15 | K18: Everton Martins | L18: ='T (15)'!K111 -> 21
I19: 16º | J19: 16 | K19: Éverton Amaral | L19: ='T (16)'!K111 -> 21
A20: 46206 | B20: 0.625 | C20: Austrália | D20: n | E20: x | F20: d | G20: Egito | I20: 17º | J20: 17 | K20: Miguel Amaral | L20: ='T (17)'!K111 -> 16
I21: 18º | J21: 18 | K21: João Vinícius | L21: ='T (18)'!K111 -> 12
A22: 46206 | B22: 0.79166667 | C22: Argentina | D22: n | E22: x | F22: d | G22: Cabo Verde | I22: 19º | J22: 19 | K22: Luciana D´Assunção | L22: ='T (19)'!K111 -> 15
I23: 20º | J23: 20 | K23: Marco Aurélio | L23: ='T (20)'!K111 -> 20
A24: 46206 | B24: 0.9375 | C24: Colômbia | D24: n | E24: x | F24: d | G24: Gana | I24: 21º | J24: 21 | K24: Heitor Medeiros | L24: ='T (21)'!K111 -> 15
I25: 22º | J25: 22 | K25: Joselito Batista | L25: ='T (22)'!K111 -> 15
A26: 46207 | B26: 0.58333333 | E26: x | I26: 23º | J26: 23 | K26: Joan Nunes | L26: ='T (23)'!K111 -> 18
I27: 24º | J27: 24 | K27: Paulo Melo | L27: ='T (24)'!K111 -> 18
A28: 46207 | B28: 0.75 | E28: x | I28: 25º | J28: 25 | K28: Jarley Jerônimo | L28: ='T (25)'!K111 -> 20
I29: 26º | J29: 26 | K29: Ana Kathleen | L29: ='T (26)'!K111 -> 19
I30: 27º | J30: 27 | K30: Fernanda Beatriz | L30: ='T (27)'!K111 -> 16
A31: 46208 | B31: 0.70833333 | E31: x | H31: D | I31: 28º | J31: 28 | K31: Arthur Mariz | L31: ='T (28)'!K111 -> 14
I32: 29º | J32: 29 | K32: Larissa Mariz | L32: ='T (29)'!K111 -> 16
A33: 46208 | B33: 0.875 | E33: x | I33: 30º | J33: 30 | K33: Francisco de Assis | L33: ='T (30)'!K111 -> 12
I34: 31º | J34: 31 | K34: Rommel Leite | L34: ='T (31)'!K111 -> 18
A35: 46209 | B35: 0.66666667 | E35: x | I35: 32º | J35: 32 | K35: Marcelo Jacinto | L35: ='T (32)'!K111 -> 25
I36: 33º | J36: 33 | K36: Nelson Henrique | L36: ='T (33)'!K111 -> 11
A37: 46209 | B37: 0.875 | E37: x | I37: 34º | J37: 34 | K37: José Carlos | L37: ='T (34)'!K111 -> 11
I38: 35º | J38: 35 | K38: Alber Garcia | L38: ='T (35)'!K111 -> 14
A39: 46210 | B39: 0.54166667 | E39: x | I39: 36º | J39: 36 | K39: Victor Hugo | L39: ='T (36)'!K111 -> 17
I40: 37º | J40: 37 | K40: Norman George | L40: ='T (37)'!K111 -> 21
A41: 46210 | B41: 0.70833333 | E41: x | I41: 38º | J41: 38 | K41: Luiz Felipe | L41: ='T (38)'!K111 -> 19
...

Sheet T (1)
A1: Nome | C1: Felipe Barros | S1: empate | X1: vitoria A | AD1: Vitiria B
O2: ok | P2: ok
D3: PARTICIPANTE | H3: OFICIAL | K3: PONTOS
A4: =TABELA!A4 -> 46201 | B4: =TABELA!B4 -> 0.66666667 | C4: =TABELA!C4 -> Africa do Sul | D4: 0 | E4: x | F4: 2 | G4: =TABELA!G4 -> Canadá | H4: =TABELA!D4 -> 0 | I4: x | J4: =TABELA!F4 -> 1 | K4: =O4+P4+U4+AA4+AF4 -> 7 | L4: a | O4: =IF(D4=H4,2,0) -> 2 | P4: =IF(F4=J4,2,0) -> 0 | Q4: =IF(O4+P4=4,5,0) -> 0 | S4: =IF(D4=F4,1,0) -> 0 | T4: =IF(H4=J4,1,0) -> 0 | U4: =IF(S4+T4=2,5,0) -> 0 | V4: =IF(Q4=5,0,U4) -> 0 | X4: =IF(D4>F4,1,0) -> 0 | Y4: =IF(H4>J4,1,0) -> 0 | Z4: =IF(X4+Y4=2,5,0) -> 0 | AA4: =IF(H4="n",0,Z4) -> 0 | AB4: =IF(Q4=5,0,AA4) -> 0 | AD4: =IF(D4<F4,1,0) -> 1 | AE4: =IF(H4<J4,1,0) -> 1 | AF4: =IF(AD4+AE4=2,5,0) -> 5 | AG4: =IF(Q4=5,0,AF4) -> 5
A5: =TABELA!A5 -> 46202 | B5: =TABELA!B5 -> 0.58333333 | C5: =TABELA!C5 -> Brasil | D5: 1 | E5: x | F5: 2 | G5: =TABELA!G5 -> Japão | H5: =TABELA!D5 -> 2 | I5: x | J5: =TABELA!F5 -> 1 | K5: =O5+P5+U5+AA5+AF5 -> 0 | O5: =IF(D5=H5,2,0) -> 0 | P5: =IF(F5=J5,2,0) -> 0 | Q5: =IF(O5+P5=4,5,0) -> 0 | S5: =IF(D5=F5,1,0) -> 0 | T5: =IF(H5=J5,1,0) -> 0 | U5: =IF(S5+T5=2,5,0) -> 0 | V5: =IF(Q5=5,0,U5) -> 0 | X5: =IF(D5>F5,1,0) -> 0 | Y5: =IF(H5>J5,1,0) -> 1 | Z5: =IF(X5+Y5=2,5,0) -> 0 | AA5: =IF(H5="n",0,Z5) -> 0 | AB5: =IF(Q5=5,0,AA5) -> 0 | AD5: =IF(D5<F5,1,0) -> 1 | AE5: =IF(H5<J5,1,0) -> 0 | AF5: =IF(AD5+AE5=2,5,0) -> 0 | AG5: =IF(Q5=5,0,AF5) -> 0
A6: =TABELA!A6 -> 46202 | B6: =TABELA!B6 -> 0.72916667 | C6: =TABELA!C6 -> Alemanha | D6: 4 | E6: x | F6: 1 | G6: =TABELA!G6 -> Paraguai | H6: =TABELA!D6 -> 1 | I6: x | J6: =TABELA!F6 -> 1 | K6: =O6+P6+U6+AA6+AF6 -> 2 | O6: =IF(D6=H6,2,0) -> 0 | P6: =IF(F6=J6,2,0) -> 2 | Q6: =IF(O6+P6=4,5,0) -> 0 | S6: =IF(D6=F6,1,0) -> 0 | T6: =IF(H6=J6,1,0) -> 1 | U6: =IF(S6+T6=2,5,0) -> 0 | V6: =IF(Q6=5,0,U6) -> 0 | X6: =IF(D6>F6,1,0) -> 1 | Y6: =IF(H6>J6,1,0) -> 0 | Z6: =IF(X6+Y6=2,5,0) -> 0 | AA6: =IF(H6="n",0,Z6) -> 0 | AB6: =IF(Q6=5,0,AA6) -> 0 | AD6: =IF(D6<F6,1,0) -> 0 | AE6: =IF(H6<J6,1,0) -> 0 | AF6: =IF(AD6+AE6=2,5,0) -> 0 | AG6: =IF(Q6=5,0,AF6) -> 0
A7: =TABELA!A7 -> 46202 | B7: =TABELA!B7 -> 0.91666667 | C7: =TABELA!C7 -> Holanda | D7: 3 | E7: x | F7: 1 | G7: =TABELA!G7 -> Marrocos | H7: =TABELA!D7 -> 1 | I7: x | J7: =TABELA!F7 -> 1 | K7: =O7+P7+U7+AA7+AF7 -> 2 | O7: =IF(D7=H7,2,0) -> 0 | P7: =IF(F7=J7,2,0) -> 2 | Q7: =IF(O7+P7=4,5,0) -> 0 | S7: =IF(D7=F7,1,0) -> 0 | T7: =IF(H7=J7,1,0) -> 1 | U7: =IF(S7+T7=2,5,0) -> 0 | V7: =IF(Q7=5,0,U7) -> 0 | X7: =IF(D7>F7,1,0) -> 1 | Y7: =IF(H7>J7,1,0) -> 0 | Z7: =IF(X7+Y7=2,5,0) -> 0 | AA7: =IF(H7="n",0,Z7) -> 0 | AB7: =IF(Q7=5,0,AA7) -> 0 | AD7: =IF(D7<F7,1,0) -> 0 | AE7: =IF(H7<J7,1,0) -> 0 | AF7: =IF(AD7+AE7=2,5,0) -> 0 | AG7: =IF(Q7=5,0,AF7) -> 0
A8: =TABELA!A8 -> 46203 | B8: =TABELA!B8 -> 0.58333333 | C8: =TABELA!C8 -> Cost. do Marf. | D8: 1 | E8: x | F8: 2 | G8: =TABELA!G8 -> Noruega | H8: =TABELA!D8 -> n | I8: x | J8: =TABELA!F8 -> d | K8: =O8+P8+U8+AA8+AF8 -> 0 | O8: =IF(D8=H8,2,0) -> 0 | P8: =IF(F8=J8,2,0) -> 0 | Q8: =IF(O8+P8=4,5,0) -> 0 | S8: =IF(D8=F8,1,0) -> 0 | T8: =IF(H8=J8,1,0) -> 0 | U8: =IF(S8+T8=2,5,0) -> 0 | V8: =IF(Q8=5,0,U8) -> 0 | X8: =IF(D8>F8,1,0) -> 0 | Y8: =IF(H8>J8,1,0) -> 1 | Z8: =IF(X8+Y8=2,5,0) -> 0 | AA8: =IF(H8="n",0,Z8) -> 0 | AB8: =IF(Q8=5,0,AA8) -> 0 | AD8: =IF(D8<F8,1,0) -> 1 | AE8: =IF(H8<J8,1,0) -> 0 | AF8: =IF(AD8+AE8=2,5,0) -> 0 | AG8: =IF(Q8=5,0,AF8) -> 0
A9: =TABELA!A9 -> 46203 | B9: =TABELA!B9 -> 0.75 | C9: =TABELA!C9 -> França | D9: 3 | E9: x | F9: 0 | G9: =TABELA!G9 -> Suécia | H9: =TABELA!D9 -> n | I9: x | J9: =TABELA!F9 -> d | K9: =O9+P9+U9+AA9+AF9 -> 0 | O9: =IF(D9=H9,2,0) -> 0 | P9: =IF(F9=J9,2,0) -> 0 | Q9: =IF(O9+P9=4,5,0) -> 0 | S9: =IF(D9=F9,1,0) -> 0 | T9: =IF(H9=J9,1,0) -> 0 | U9: =IF(S9+T9=2,5,0) -> 0 | V9: =IF(Q9=5,0,U9) -> 0 | X9: =IF(D9>F9,1,0) -> 1 | Y9: =IF(H9>J9,1,0) -> 1 | Z9: =IF(X9+Y9=2,5,0) -> 5 | AA9: =IF(H9="n",0,Z9) -> 0 | AB9: =IF(Q9=5,0,AA9) -> 0 | AD9: =IF(D9<F9,1,0) -> 0 | AE9: =IF(H9<J9,1,0) -> 0 | AF9: =IF(AD9+AE9=2,5,0) -> 0 | AG9: =IF(Q9=5,0,AF9) -> 0
A11: =TABELA!A11 -> 46203 | B11: =TABELA!B11 -> 0.91666667 | C11: =TABELA!C11 -> México | D11: 1 | E11: x | F11: 2 | G11: =TABELA!G11 -> Equador | H11: =TABELA!D11 -> n | I11: x | J11: =TABELA!F11 -> d | K11: =O11+P11+U11+AA11+AF11 -> 0 | L11: B | O11: =IF(D11=H11,2,0) -> 0 | P11: =IF(F11=J11,2,0) -> 0 | Q11: =IF(O11+P11=4,5,0) -> 0 | S11: =IF(D11=F11,1,0) -> 0 | T11: =IF(H11=J11,1,0) -> 0 | U11: =IF(S11+T11=2,5,0) -> 0 | V11: =IF(Q11=5,0,U11) -> 0 | X11: =IF(D11>F11,1,0) -> 0 | Y11: =IF(H11>J11,1,0) -> 1 | Z11: =IF(X11+Y11=2,5,0) -> 0 | AA11: =IF(H11="n",0,Z11) -> 0 | AB11: =IF(Q11=5,0,AA11) -> 0 | AD11: =IF(D11<F11,1,0) -> 1 | AE11: =IF(H11<J11,1,0) -> 0 | AF11: =IF(AD11+AE11=2,5,0) -> 0 | AG11: =IF(Q11=5,0,AF11) -> 0
A12: =TABELA!A12 -> 46204 | B12: =TABELA!B12 -> 0.54166667 | C12: =TABELA!C12 -> Inglaterra | D12: 3 | E12: x | F12: 1 | G12: =TABELA!G12 -> Congo | H12: =TABELA!D12 -> n | I12: x | J12: =TABELA!F12 -> d | K12: =O12+P12+U12+AA12+AF12 -> 0 | O12: =IF(D12=H12,2,0) -> 0 | P12: =IF(F12=J12,2,0) -> 0 | Q12: =IF(O12+P12=4,5,0) -> 0 | S12: =IF(D12=F12,1,0) -> 0 | T12: =IF(H12=J12,1,0) -> 0 | U12: =IF(S12+T12=2,5,0) -> 0 | V12: =IF(Q12=5,0,U12) -> 0 | X12: =IF(D12>F12,1,0) -> 1 | Y12: =IF(H12>J12,1,0) -> 1 | Z12: =IF(X12+Y12=2,5,0) -> 5 | AA12: =IF(H12="n",0,Z12) -> 0 | AB12: =IF(Q12=5,0,AA12) -> 0 | AD12: =IF(D12<F12,1,0) -> 0 | AE12: =IF(H12<J12,1,0) -> 0 | AF12: =IF(AD12+AE12=2,5,0) -> 0 | AG12: =IF(Q12=5,0,AF12) -> 0
A13: =TABELA!A13 -> 46204 | B13: =TABELA!B13 -> 0.70833333 | C13: =TABELA!C13 -> Bélgica | D13: 1 | E13: x | F13: 2 | G13: =TABELA!G13 -> Senegal | H13: =TABELA!D13 -> n | I13: x | J13: =TABELA!F13 -> d | K13: =O13+P13+U13+AA13+AF13 -> 0 | O13: =IF(D13=H13,2,0) -> 0 | P13: =IF(F13=J13,2,0) -> 0 | Q13: =IF(O13+P13=4,5,0) -> 0 | S13: =IF(D13=F13,1,0) -> 0 | T13: =IF(H13=J13,1,0) -> 0 | U13: =IF(S13+T13=2,5,0) -> 0 | V13: =IF(Q13=5,0,U13) -> 0 | X13: =IF(D13>F13,1,0) -> 0 | Y13: =IF(H13>J13,1,0) -> 1 | Z13: =IF(X13+Y13=2,5,0) -> 0 | AA13: =IF(H13="n",0,Z13) -> 0 | AB13: =IF(Q13=5,0,AA13) -> 0 | AD13: =IF(D13<F13,1,0) -> 1 | AE13: =IF(H13<J13,1,0) -> 0 | AF13: =IF(AD13+AE13=2,5,0) -> 0 | AG13: =IF(Q13=5,0,AF13) -> 0
A14: =TABELA!A14 -> 46204 | B14: =TABELA!B14 -> 0.875 | C14: =TABELA!C14 -> Estados Unidos | D14: 3 | E14: x | F14: 0 | G14: =TABELA!G14 -> Bósnia | H14: =TABELA!D14 -> n | I14: x | J14: =TABELA!F14 -> d | K14: =O14+P14+U14+AA14+AF14 -> 0 | O14: =IF(D14=H14,2,0) -> 0 | P14: =IF(F14=J14,2,0) -> 0 | Q14: =IF(O14+P14=4,5,0) -> 0 | S14: =IF(D14=F14,1,0) -> 0 | T14: =IF(H14=J14,1,0) -> 0 | U14: =IF(S14+T14=2,5,0) -> 0 | V14: =IF(Q14=5,0,U14) -> 0 | X14: =IF(D14>F14,1,0) -> 1 | Y14: =IF(H14>J14,1,0) -> 1 | Z14: =IF(X14+Y14=2,5,0) -> 5 | AA14: =IF(H14="n",0,Z14) -> 0 | AB14: =IF(Q14=5,0,AA14) -> 0 | AD14: =IF(D14<F14,1,0) -> 0 | AE14: =IF(H14<J14,1,0) -> 0 | AF14: =IF(AD14+AE14=2,5,0) -> 0 | AG14: =IF(Q14=5,0,AF14) -> 0
A15: =TABELA!A15 -> 46205 | B15: =TABELA!B15 -> 0.66666667 | C15: Espanha | D15: 2 | E15: x | F15: 0 | G15: =TABELA!G15 -> Áustria | H15: =TABELA!D15 -> n | I15: x | J15: =TABELA!F15 -> d | K15: =O15+P15+U15+AA15+AF15 -> 0 | O15: =IF(D15=H15,2,0) -> 0 | P15: =IF(F15=J15,2,0) -> 0 | Q15: =IF(O15+P15=4,5,0) -> 0 | S15: =IF(D15=F15,1,0) -> 0 | T15: =IF(H15=J15,1,0) -> 0 | U15: =IF(S15+T15=2,5,0) -> 0 | V15: =IF(Q15=5,0,U15) -> 0 | X15: =IF(D15>F15,1,0) -> 1 | Y15: =IF(H15>J15,1,0) -> 1 | Z15: =IF(X15+Y15=2,5,0) -> 5 | AA15: =IF(H15="n",0,Z15) -> 0 | AB15: =IF(Q15=5,0,AA15) -> 0 | AD15: =IF(D15<F15,1,0) -> 0 | AE15: =IF(H15<J15,1,0) -> 0 | AF15: =IF(AD15+AE15=2,5,0) -> 0 | AG15: =IF(Q15=5,0,AF15) -> 0
A16: =TABELA!A16 -> 46205 | B16: =TABELA!B16 -> 0.83333333 | C16: =TABELA!C16 -> Portugal | D16: 3 | E16: x | F16: 1 | G16: =TABELA!G16 -> Croácia | H16: =TABELA!D16 -> n | I16: x | J16: =TABELA!F16 -> d | K16: =O16+P16+U16+AA16+AF16 -> 0 | O16: =IF(D16=H16,2,0) -> 0 | P16: =IF(F16=J16,2,0) -> 0 | Q16: =IF(O16+P16=4,5,0) -> 0 | S16: =IF(D16=F16,1,0) -> 0 | T16: =IF(H16=J16,1,0) -> 0 | U16: =IF(S16+T16=2,5,0) -> 0 | V16: =IF(Q16=5,0,U16) -> 0 | X16: =IF(D16>F16,1,0) -> 1 | Y16: =IF(H16>J16,1,0) -> 1 | Z16: =IF(X16+Y16=2,5,0) -> 5 | AA16: =IF(H16="n",0,Z16) -> 0 | AB16: =IF(Q16=5,0,AA16) -> 0 | AD16: =IF(D16<F16,1,0) -> 0 | AE16: =IF(H16<J16,1,0) -> 0 | AF16: =IF(AD16+AE16=2,5,0) -> 0 | AG16: =IF(Q16=5,0,AF16) -> 0
A18: =TABELA!A18 -> 46206 | B18: =TABELA!B18 -> 0 | C18: =TABELA!C18 -> Suíça | D18: 2 | E18: x | F18: 1 | G18: =TABELA!G18 -> Argélia | H18: =TABELA!D18 -> n | I18: x | J18: =TABELA!F18 -> d | K18: =O18+P18+U18+AA18+AF18 -> 0 | L18: C | O18: =IF(D18=H18,2,0) -> 0 | P18: =IF(F18=J18,2,0) -> 0 | Q18: =IF(O18+P18=4,5,0) -> 0 | S18: =IF(D18=F18,1,0) -> 0 | T18: =IF(H18=J18,1,0) -> 0 | U18: =IF(S18+T18=2,5,0) -> 0 | V18: =IF(Q18=5,0,U18) -> 0 | X18: =IF(D18>F18,1,0) -> 1 | Y18: =IF(H18>J18,1,0) -> 1 | Z18: =IF(X18+Y18=2,5,0) -> 5 | AA18: =IF(H18="n",0,Z18) -> 0 | AB18: =IF(Q18=5,0,AA18) -> 0 | AD18: =IF(D18<F18,1,0) -> 0 | AE18: =IF(H18<J18,1,0) -> 0 | AF18: =IF(AD18+AE18=2,5,0) -> 0 | AG18: =IF(Q18=5,0,AF18) -> 0
A20: =TABELA!A20 -> 46206 | B20: =TABELA!B20 -> 0.625 | C20: =TABELA!C20 -> Austrália | D20: 2 | E20: x | F20: 2 | G20: =TABELA!G20 -> Egito | H20: =TABELA!D20 -> n | I20: x | J20: =TABELA!F20 -> d | K20: =O20+P20+U20+AA20+AF20 -> 0 | O20: =IF(D20=H20,2,0) -> 0 | P20: =IF(F20=J20,2,0) -> 0 | Q20: =IF(O20+P20=4,5,0) -> 0 | S20: =IF(D20=F20,1,0) -> 1 | T20: =IF(H20=J20,1,0) -> 0 | U20: =IF(S20+T20=2,5,0) -> 0 | V20: =IF(Q20=5,0,U20) -> 0 | X20: =IF(D20>F20,1,0) -> 0 | Y20: =IF(H20>J20,1,0) -> 1 | Z20: =IF(X20+Y20=2,5,0) -> 0 | AA20: =IF(H20="n",0,Z20) -> 0 | AB20: =IF(Q20=5,0,AA20) -> 0 | AD20: =IF(D20<F20,1,0) -> 0 | AE20: =IF(H20<J20,1,0) -> 0 | AF20: =IF(AD20+AE20=2,5,0) -> 0 | AG20: =IF(Q20=5,0,AF20) -> 0
A22: =TABELA!A22 -> 46206 | B22: =TABELA!B22 -> 0.79166667 | C22: =TABELA!C22 -> Argentina | D22: 4 | E22: x | F22: 1 | G22: =TABELA!G22 -> Cabo Verde | H22: =TABELA!D22 -> n | I22: x | J22: =TABELA!F22 -> d | K22: =O22+P22+U22+AA22+AF22 -> 0 | O22: =IF(D22=H22,2,0) -> 0 | P22: =IF(F22=J22,2,0) -> 0 | Q22: =IF(O22+P22=4,5,0) -> 0 | S22: =IF(D22=F22,1,0) -> 0 | T22: =IF(H22=J22,1,0) -> 0 | U22: =IF(S22+T22=2,5,0) -> 0 | V22: =IF(Q22=5,0,U22) -> 0 | X22: =IF(D22>F22,1,0) -> 1 | Y22: =IF(H22>J22,1,0) -> 1 | Z22: =IF(X22+Y22=2,5,0) -> 5 | AA22: =IF(H22="n",0,Z22) -> 0 | AB22: =IF(Q22=5,0,AA22) -> 0 | AD22: =IF(D22<F22,1,0) -> 0 | AE22: =IF(H22<J22,1,0) -> 0 | AF22: =IF(AD22+AE22=2,5,0) -> 0 | AG22: =IF(Q22=5,0,AF22) -> 0
A24: =TABELA!A24 -> 46206 | B24: =TABELA!B24 -> 0.9375 | C24: Colômbia | D24: 1 | E24: x | F24: 2 | G24: Gana | H24: =TABELA!D24 -> n | I24: x | J24: =TABELA!F24 -> d | K24: =O24+P24+U24+AA24+AF24 -> 0 | O24: =IF(D24=H24,2,0) -> 0 | P24: =IF(F24=J24,2,0) -> 0 | Q24: =IF(O24+P24=4,5,0) -> 0 | S24: =IF(D24=F24,1,0) -> 0 | T24: =IF(H24=J24,1,0) -> 0 | U24: =IF(S24+T24=2,5,0) -> 0 | V24: =IF(Q24=5,0,U24) -> 0 | X24: =IF(D24>F24,1,0) -> 0 | Y24: =IF(H24>J24,1,0) -> 1 | Z24: =IF(X24+Y24=2,5,0) -> 0 | AA24: =IF(H24="n",0,Z24) -> 0 | AB24: =IF(Q24=5,0,AA24) -> 0 | AD24: =IF(D24<F24,1,0) -> 1 | AE24: =IF(H24<J24,1,0) -> 0 | AF24: =IF(AD24+AE24=2,5,0) -> 0 | AG24: =IF(Q24=5,0,AF24) -> 0
A26: 46207 | B26: 0.58333333 | E26: x | H26: n | I26: x | J26: d | K26: =O26+P26+U26+AA26+AF26 -> 0 | O26: =IF(D26=H26,2,0) -> 0 | P26: =IF(F26=J26,2,0) -> 0 | Q26: =IF(O26+P26=4,5,0) -> 0 | S26: =IF(D26=F26,1,0) -> 1 | T26: =IF(H26=J26,1,0) -> 0 | U26: =IF(S26+T26=2,5,0) -> 0 | V26: =IF(Q26=5,0,U26) -> 0 | X26: =IF(D26>F26,1,0) -> 0 | Y26: =IF(H26>J26,1,0) -> 1 | Z26: =IF(X26+Y26=2,5,0) -> 0 | AA26: =IF(H26="n",0,Z26) -> 0 | AB26: =IF(Q26=5,0,AA26) -> 0 | AD26: =IF(D26<F26,1,0) -> 0 | AE26: =IF(H26<J26,1,0) -> 0 | AF26: =IF(AD26+AE26=2,5,0) -> 0 | AG26: =IF(Q26=5,0,AF26) -> 0
A28: 46207 | B28: 0.75 | E28: x | H28: n | I28: x | J28: d | K28: =O28+P28+U28+AA28+AF28 -> 0 | O28: =IF(D28=H28,2,0) -> 0 | P28: =IF(F28=J28,2,0) -> 0 | Q28: =IF(O28+P28=4,5,0) -> 0 | S28: =IF(D28=F28,1,0) -> 1 | T28: =IF(H28=J28,1,0) -> 0 | U28: =IF(S28+T28=2,5,0) -> 0 | V28: =IF(Q28=5,0,U28) -> 0 | X28: =IF(D28>F28,1,0) -> 0 | Y28: =IF(H28>J28,1,0) -> 1 | Z28: =IF(X28+Y28=2,5,0) -> 0 | AA28: =IF(H28="n",0,Z28) -> 0 | AB28: =IF(Q28=5,0,AA28) -> 0 | AD28: =IF(D28<F28,1,0) -> 0 | AE28: =IF(H28<J28,1,0) -> 0 | AF28: =IF(AD28+AE28=2,5,0) -> 0 | AG28: =IF(Q28=5,0,AF28) -> 0
A31: 46208 | B31: 0.70833333 | E31: x | H31: n | I31: x | J31: d | K31: =O31+P31+U31+AA31+AF31 -> 0 | L31: D | O31: =IF(D31=H31,2,0) -> 0 | P31: =IF(F31=J31,2,0) -> 0 | Q31: =IF(O31+P31=4,5,0) -> 0 | S31: =IF(D31=F31,1,0) -> 1 | T31: =IF(H31=J31,1,0) -> 0 | U31: =IF(S31+T31=2,5,0) -> 0 | V31: =IF(Q31=5,0,U31) -> 0 | X31: =IF(D31>F31,1,0) -> 0 | Y31: =IF(H31>J31,1,0) -> 1 | Z31: =IF(X31+Y31=2,5,0) -> 0 | AA31: =IF(H31="n",0,Z31) -> 0 | AB31: =IF(Q31=5,0,AA31) -> 0 | AD31: =IF(D31<F31,1,0) -> 0 | AE31: =IF(H31<J31,1,0) -> 0 | AF31: =IF(AD31+AE31=2,5,0) -> 0 | AG31: =IF(Q31=5,0,AF31) -> 0
A33: 46208 | B33: 0.875 | E33: x | H33: n | I33: x | J33: d | K33: =O33+P33+U33+AA33+AF33 -> 0 | O33: =IF(D33=H33,2,0) -> 0 | P33: =IF(F33=J33,2,0) -> 0 | Q33: =IF(O33+P33=4,5,0) -> 0 | S33: =IF(D33=F33,1,0) -> 1 | T33: =IF(H33=J33,1,0) -> 0 | U33: =IF(S33+T33=2,5,0) -> 0 | V33: =IF(Q33=5,0,U33) -> 0 | X33: =IF(D33>F33,1,0) -> 0 | Y33: =IF(H33>J33,1,0) -> 1 | Z33: =IF(X33+Y33=2,5,0) -> 0 | AA33: =IF(H33="n",0,Z33) -> 0 | AB33: =IF(Q33=5,0,AA33) -> 0 | AD33: =IF(D33<F33,1,0) -> 0 | AE33: =IF(H33<J33,1,0) -> 0 | AF33: =IF(AD33+AE33=2,5,0) -> 0 | AG33: =IF(Q33=5,0,AF33) -> 0
A35: 46209 | B35: 0.66666667 | E35: x | H35: n | I35: x | J35: d | K35: =O35+P35+U35+AA35+AF35 -> 0 | O35: =IF(D35=H35,2,0) -> 0 | P35: =IF(F35=J35,2,0) -> 0 | Q35: =IF(O35+P35=4,5,0) -> 0 | S35: =IF(D35=F35,1,0) -> 1 | T35: =IF(H35=J35,1,0) -> 0 | U35: =IF(S35+T35=2,5,0) -> 0 | V35: =IF(Q35=5,0,U35) -> 0 | X35: =IF(D35>F35,1,0) -> 0 | Y35: =IF(H35>J35,1,0) -> 1 | Z35: =IF(X35+Y35=2,5,0) -> 0 | AA35: =IF(H35="n",0,Z35) -> 0 | AB35: =IF(Q35=5,0,AA35) -> 0 | AD35: =IF(D35<F35,1,0) -> 0 | AE35: =IF(H35<J35,1,0) -> 0 | AF35: =IF(AD35+AE35=2,5,0) -> 0 | AG35: =IF(Q35=5,0,AF35) -> 0
A37: 46209 | B37: 0.875 | E37: x | H37: n | I37: x | J37: d | K37: =O37+P37+U37+AA37+AF37 -> 0 | O37: =IF(D37=H37,2,0) -> 0 | P37: =IF(F37=J37,2,0) -> 0 | Q37: =IF(O37+P37=4,5,0) -> 0 | S37: =IF(D37=F37,1,0) -> 1 | T37: =IF(H37=J37,1,0) -> 0 | U37: =IF(S37+T37=2,5,0) -> 0 | V37: =IF(Q37=5,0,U37) -> 0 | X37: =IF(D37>F37,1,0) -> 0 | Y37: =IF(H37>J37,1,0) -> 1 | Z37: =IF(X37+Y37=2,5,0) -> 0 | AA37: =IF(H37="n",0,Z37) -> 0 | AB37: =IF(Q37=5,0,AA37) -> 0 | AD37: =IF(D37<F37,1,0) -> 0 | AE37: =IF(H37<J37,1,0) -> 0 | AF37: =IF(AD37+AE37=2,5,0) -> 0 | AG37: =IF(Q37=5,0,AF37) -> 0
A39: 46210 | B39: 0.54166667 | E39: x | H39: n | I39: x | J39: d | K39: =O39+P39+U39+AA39+AF39 -> 0 | O39: =IF(D39=H39,2,0) -> 0 | P39: =IF(F39=J39,2,0) -> 0 | Q39: =IF(O39+P39=4,5,0) -> 0 | S39: =IF(D39=F39,1,0) -> 1 | T39: =IF(H39=J39,1,0) -> 0 | U39: =IF(S39+T39=2,5,0) -> 0 | V39: =IF(Q39=5,0,U39) -> 0 | X39: =IF(D39>F39,1,0) -> 0 | Y39: =IF(H39>J39,1,0) -> 1 | Z39: =IF(X39+Y39=2,5,0) -> 0 | AA39: =IF(H39="n",0,Z39) -> 0 | AB39: =IF(Q39=5,0,AA39) -> 0 | AD39: =IF(D39<F39,1,0) -> 0 | AE39: =IF(H39<J39,1,0) -> 0 | AF39: =IF(AD39+AE39=2,5,0) -> 0 | AG39: =IF(Q39=5,0,AF39) -> 0
A41: 46210 | B41: 0.70833333 | E41: x | H41: n | I41: x | J41: d | K41: =O41+P41+U41+AA41+AF41 -> 0 | O41: =IF(D41=H41,2,0) -> 0 | P41: =IF(F41=J41,2,0) -> 0 | Q41: =IF(O41+P41=4,5,0) -> 0 | S41: =IF(D41=F41,1,0) -> 1 | T41: =IF(H41=J41,1,0) -> 0 | U41: =IF(S41+T41=2,5,0) -> 0 | V41: =IF(Q41=5,0,U41) -> 0 | X41: =IF(D41>F41,1,0) -> 0 | Y41: =IF(H41>J41,1,0) -> 1 | Z41: =IF(X41+Y41=2,5,0) -> 0 | AA41: =IF(H41="n",0,Z41) -> 0 | AB41: =IF(Q41=5,0,AA41) -> 0 | AD41: =IF(D41<F41,1,0) -> 0 | AE41: =IF(H41<J41,1,0) -> 0 | AF41: =IF(AD41+AE41=2,5,0) -> 0 | AG41: =IF(Q41=5,0,AF41) -> 0
A44: 46212 | B44: 0.70833333 | E44: x | H44: n | I44: x | J44: d | K44: =O44+P44+U44+AA44+AF44 -> 0 | L44: E | O44: =IF(D44=H44,2,0) -> 0 | P44: =IF(F44=J44,2,0) -> 0 | Q44: =IF(O44+P44=4,5,0) -> 0 | S44: =IF(D44=F44,1,0) -> 1 | T44: =IF(H44=J44,1,0) -> 0 | U44: =IF(S44+T44=2,5,0) -> 0 | V44: =IF(Q44=5,0,U44) -> 0 | X44: =IF(D44>F44,1,0) -> 0 | Y44: =IF(H44>J44,1,0) -> 1 | Z44: =IF(X44+Y44=2,5,0) -> 0 | AA44: =IF(H44="n",0,Z44) -> 0 | AB44: =IF(Q44=5,0,AA44) -> 0 | AD44: =IF(D44<F44,1,0) -> 0 | AE44: =IF(H44<J44,1,0) -> 0 | AF44: =IF(AD44+AE44=2,5,0) -> 0 | AG44: =IF(Q44=5,0,AF44) -> 0
A46: 46213 | B46: 0.66666667 | E46: x | H46: n | I46: x | J46: d | K46: =O46+P46+U46+AA46+AF46 -> 0 | O46: =IF(D46=H46,2,0) -> 0 | P46: =IF(F46=J46,2,0) -> 0 | Q46: =IF(O46+P46=4,5,0) -> 0 | S46: =IF(D46=F46,1,0) -> 1 | T46: =IF(H46=J46,1,0) -> 0 | U46: =IF(S46+T46=2,5,0) -> 0 | V46: =IF(Q46=5,0,U46) -> 0 | X46: =IF(D46>F46,1,0) -> 0 | Y46: =IF(H46>J46,1,0) -> 1 | Z46: =IF(X46+Y46=2,5,0) -> 0 | AA46: =IF(H46="n",0,Z46) -> 0 | AB46: =IF(Q46=5,0,AA46) -> 0 | AD46: =IF(D46<F46,1,0) -> 0 | AE46: =IF(H46<J46,1,0) -> 0 | AF46: =IF(AD46+AE46=2,5,0) -> 0 | AG46: =IF(Q46=5,0,AF46) -> 0
A48: 46214 | B48: 0.75 | E48: x | H48: n | I48: x | J48: d | K48: =O48+P48+U48+AA48+AF48 -> 0 | O48: =IF(D48=H48,2,0) -> 0 | P48: =IF(F48=J48,2,0) -> 0 | Q48: =IF(O48+P48=4,5,0) -> 0 | S48: =IF(D48=F48,1,0) -> 1 | T48: =IF(H48=J48,1,0) -> 0 | U48: =IF(S48+T48=2,5,0) -> 0 | V48: =IF(Q48=5,0,U48) -> 0 | X48: =IF(D48>F48,1,0) -> 0 | Y48: =IF(H48>J48,1,0) -> 1 | Z48: =IF(X48+Y48=2,5,0) -> 0 | AA48: =IF(H48="n",0,Z48) -> 0 | AB48: =IF(Q48=5,0,AA48) -> 0 | AD48: =IF(D48<F48,1,0) -> 0 | AE48: =IF(H48<J48,1,0) -> 0 | AF48: =IF(AD48+AE48=2,5,0) -> 0 | AG48: =IF(Q48=5,0,AF48) -> 0
A50: 46214 | B50: 0.91666667 | E50: x | H50: n | I50: x | J50: d | K50: =O50+P50+U50+AA50+AF50 -> 0 | O50: =IF(D50=H50,2,0) -> 0 | P50: =IF(F50=J50,2,0) -> 0 | Q50: =IF(O50+P50=4,5,0) -> 0 | S50: =IF(D50=F50,1,0) -> 1 | T50: =IF(H50=J50,1,0) -> 0 | U50: =IF(S50+T50=2,5,0) -> 0 | V50: =IF(Q50=5,0,U50) -> 0 | X50: =IF(D50>F50,1,0) -> 0 | Y50: =IF(H50>J50,1,0) -> 1 | Z50: =IF(X50+Y50=2,5,0) -> 0 | AA50: =IF(H50="n",0,Z50) -> 0 | AB50: =IF(Q50=5,0,AA50) -> 0 | AD50: =IF(D50<F50,1,0) -> 0 | AE50: =IF(H50<J50,1,0) -> 0 | AF50: =IF(AD50+AE50=2,5,0) -> 0 | AG50: =IF(Q50=5,0,AF50) -> 0
A52: 46217 | B52: 0.66666667 | E52: x | H52: n | I52: x | J52: d | K52: =O52+P52+U52+AA52+AF52 -> 0 | O52: =IF(D52=H52,2,0) -> 0 | P52: =IF(F52=J52,2,0) -> 0 | Q52: =IF(O52+P52=4,5,0) -> 0 | S52: =IF(D52=F52,1,0) -> 1 | T52: =IF(H52=J52,1,0) -> 0 | U52: =IF(S52+T52=2,5,0) -> 0 | V52: =IF(Q52=5,0,U52) -> 0 | X52: =IF(D52>F52,1,0) -> 0 | Y52: =IF(H52>J52,1,0) -> 1 | Z52: =IF(X52+Y52=2,5,0) -> 0 | AA52: =IF(H52="n",0,Z52) -> 0 | AB52: =IF(Q52=5,0,AA52) -> 0 | AD52: =IF(D52<F52,1,0) -> 0 | AE52: =IF(H52<J52,1,0) -> 0 | AF52: =IF(AD52+AE52=2,5,0) -> 0 | AG52: =IF(Q52=5,0,AF52) -> 0
A54: 46218 | B54: 0.66666667 | E54: x | H54: n | I54: x | J54: d | K54: =O54+P54+U54+AA54+AF54 -> 0 | O54: =IF(D54=H54,2,0) -> 0 | P54: =IF(F54=J54,2,0) -> 0 | Q54: =IF(O54+P54=4,5,0) -> 0 | S54: =IF(D54=F54,1,0) -> 1 | T54: =IF(H54=J54,1,0) -> 0 | U54: =IF(S54+T54=2,5,0) -> 0 | V54: =IF(Q54=5,0,U54) -> 0 | X54: =IF(D54>F54,1,0) -> 0 | Y54: =IF(H54>J54,1,0) -> 1 | Z54: =IF(X54+Y54=2,5,0) -> 0 | AA54: =IF(H54="n",0,Z54) -> 0 | AB54: =IF(Q54=5,0,AA54) -> 0 | AD54: =IF(D54<F54,1,0) -> 0 | AE54: =IF(H54<J54,1,0) -> 0 | AF54: =IF(AD54+AE54=2,5,0) -> 0 | AG54: =IF(Q54=5,0,AF54) -> 0
A57: 46221 | B57: 0.75 | E57: x | H57: n | I57: x | J57: d | K57: =O57+P57+U57+AA57+AF57 -> 0 | L57: F | O57: =IF(D57=H57,2,0) -> 0 | P57: =IF(F57=J57,2,0) -> 0 | Q57: =IF(O57+P57=4,5,0) -> 0 | S57: =IF(D57=F57,1,0) -> 1 | T57: =IF(H57=J57,1,0) -> 0 | U57: =IF(S57+T57=2,5,0) -> 0 | V57: =IF(Q57=5,0,U57) -> 0 | X57: =IF(D57>F57,1,0) -> 0 | Y57: =IF(H57>J57,1,0) -> 1 | Z57: =IF(X57+Y57=2,5,0) -> 0 | AA57: =IF(H57="n",0,Z57) -> 0 | AB57: =IF(Q57=5,0,AA57) -> 0 | AD57: =IF(D57<F57,1,0) -> 0 | AE57: =IF(H57<J57,1,0) -> 0 | AF57: =IF(AD57+AE57=2,5,0) -> 0 | AG57: =IF(Q57=5,0,AF57) -> 0
A59: 46222 | B59: 0.66666667 | E59: x | H59: n | I59: x | J59: d | K59: =O59+P59+U59+AA59+AF59 -> 0 | O59: =IF(D59=H59,2,0) -> 0 | P59: =IF(F59=J59,2,0) -> 0 | Q59: =IF(O59+P59=4,5,0) -> 0 | S59: =IF(D59=F59,1,0) -> 1 | T59: =IF(H59=J59,1,0) -> 0 | U59: =IF(S59+T59=2,5,0) -> 0 | V59: =IF(Q59=5,0,U59) -> 0 | X59: =IF(D59>F59,1,0) -> 0 | Y59: =IF(H59>J59,1,0) -> 1 | Z59: =IF(X59+Y59=2,5,0) -> 0 | AA59: =IF(H59="n",0,Z59) -> 0 | AB59: =IF(Q59=5,0,AA59) -> 0 | AD59: =IF(D59<F59,1,0) -> 0 | AE59: =IF(H59<J59,1,0) -> 0 | AF59: =IF(AD59+AE59=2,5,0) -> 0 | AG59: =IF(Q59=5,0,AF59) -> 0
E61: x | H61: n | I61: x | J61: d | K61: =O61+P61+U61+AA61+AF61 -> 0 | O61: =IF(D61=H61,2,0) -> 0 | P61: =IF(F61=J61,2,0) -> 0 | Q61: =IF(O61+P61=4,5,0) -> 0 | S61: =IF(D61=F61,1,0) -> 1 | T61: =IF(H61=J61,1,0) -> 0 | U61: =IF(S61+T61=2,5,0) -> 0 | V61: =IF(Q61=5,0,U61) -> 0 | X61: =IF(D61>F61,1,0) -> 0 | Y61: =IF(H61>J61,1,0) -> 1 | Z61: =IF(X61+Y61=2,5,0) -> 0 | AA61: =IF(H61="n",0,Z61) -> 0 | AB61: =IF(Q61=5,0,AA61) -> 0 | AD61: =IF(D61<F61,1,0) -> 0 | AE61: =IF(H61<J61,1,0) -> 0 | AF61: =IF(AD61+AE61=2,5,0) -> 0 | AG61: =IF(Q61=5,0,AF61) -> 0
E63: x | H63: n | I63: x | J63: d | K63: =O63+P63+U63+AA63+AF63 -> 0 | O63: =IF(D63=H63,2,0) -> 0 | P63: =IF(F63=J63,2,0) -> 0 | Q63: =IF(O63+P63=4,5,0) -> 0 | S63: =IF(D63=F63,1,0) -> 1 | T63: =IF(H63=J63,1,0) -> 0 | U63: =IF(S63+T63=2,5,0) -> 0 | V63: =IF(Q63=5,0,U63) -> 0 | X63: =IF(D63>F63,1,0) -> 0 | Y63: =IF(H63>J63,1,0) -> 1 | Z63: =IF(X63+Y63=2,5,0) -> 0 | AA63: =IF(H63="n",0,Z63) -> 0 | AB63: =IF(Q63=5,0,AA63) -> 0 | AD63: =IF(D63<F63,1,0) -> 0 | AE63: =IF(H63<J63,1,0) -> 0 | AF63: =IF(AD63+AE63=2,5,0) -> 0 | AG63: =IF(Q63=5,0,AF63) -> 0
E65: x | H65: n | I65: x | J65: d | K65: =O65+P65+U65+AA65+AF65 -> 0 | O65: =IF(D65=H65,2,0) -> 0 | P65: =IF(F65=J65,2,0) -> 0 | Q65: =IF(O65+P65=4,5,0) -> 0 | S65: =IF(D65=F65,1,0) -> 1 | T65: =IF(H65=J65,1,0) -> 0 | U65: =IF(S65+T65=2,5,0) -> 0 | V65: =IF(Q65=5,0,U65) -> 0 | X65: =IF(D65>F65,1,0) -> 0 | Y65: =IF(H65>J65,1,0) -> 1 | Z65: =IF(X65+Y65=2,5,0) -> 0 | AA65: =IF(H65="n",0,Z65) -> 0 | AB65: =IF(Q65=5,0,AA65) -> 0 | AD65: =IF(D65<F65,1,0) -> 0 | AE65: =IF(H65<J65,1,0) -> 0 | AF65: =IF(AD65+AE65=2,5,0) -> 0 | AG65: =IF(Q65=5,0,AF65) -> 0
E67: x | H67: n | I67: x | J67: d | K67: =O67+P67+U67+AA67+AF67 -> 0 | O67: =IF(D67=H67,2,0) -> 0 | P67: =IF(F67=J67,2,0) -> 0 | Q67: =IF(O67+P67=4,5,0) -> 0 | S67: =IF(D67=F67,1,0) -> 1 | T67: =IF(H67=J67,1,0) -> 0 | U67: =IF(S67+T67=2,5,0) -> 0 | V67: =IF(Q67=5,0,U67) -> 0 | X67: =IF(D67>F67,1,0) -> 0 | Y67: =IF(H67>J67,1,0) -> 1 | Z67: =IF(X67+Y67=2,5,0) -> 0 | AA67: =IF(H67="n",0,Z67) -> 0 | AB67: =IF(Q67=5,0,AA67) -> 0 | AD67: =IF(D67<F67,1,0) -> 0 | AE67: =IF(H67<J67,1,0) -> 0 | AF67: =IF(AD67+AE67=2,5,0) -> 0 | AG67: =IF(Q67=5,0,AF67) -> 0
E70: x | H70: n | I70: x | J70: d | K70: =O70+P70+U70+AA70+AF70 -> 0 | L70: G | O70: =IF(D70=H70,2,0) -> 0 | P70: =IF(F70=J70,2,0) -> 0 | Q70: =IF(O70+P70=4,5,0) -> 0 | S70: =IF(D70=F70,1,0) -> 1 | T70: =IF(H70=J70,1,0) -> 0 | U70: =IF(S70+T70=2,5,0) -> 0 | V70: =IF(Q70=5,0,U70) -> 0 | X70: =IF(D70>F70,1,0) -> 0 | Y70: =IF(H70>J70,1,0) -> 1 | Z70: =IF(X70+Y70=2,5,0) -> 0 | AA70: =IF(H70="n",0,Z70) -> 0 | AB70: =IF(Q70=5,0,AA70) -> 0 | AD70: =IF(D70<F70,1,0) -> 0 | AE70: =IF(H70<J70,1,0) -> 0 | AF70: =IF(AD70+AE70=2,5,0) -> 0 | AG70: =IF(Q70=5,0,AF70) -> 0
...

Sheet T (2)
A1: Nome | C1: Erick Maia | S1: empate | X1: vitoria A | AD1: Vitiria B
O2: ok | P2: ok
D3: PARTICIPANTE | H3: OFICIAL | K3: PONTOS
A4: =TABELA!A4 -> 46201 | B4: =TABELA!B4 -> 0.66666667 | C4: =TABELA!C4 -> Africa do Sul | D4: 0 | E4: x | F4: 2 | G4: =TABELA!G4 -> Canadá | H4: =TABELA!D4 -> 0 | I4: x | J4: =TABELA!F4 -> 1 | K4: =O4+P4+U4+AA4+AF4 -> 7 | L4: a | O4: =IF(D4=H4,2,0) -> 2 | P4: =IF(F4=J4,2,0) -> 0 | Q4: =IF(O4+P4=4,5,0) -> 0 | S4: =IF(D4=F4,1,0) -> 0 | T4: =IF(H4=J4,1,0) -> 0 | U4: =IF(S4+T4=2,5,0) -> 0 | V4: =IF(Q4=5,0,U4) -> 0 | X4: =IF(D4>F4,1,0) -> 0 | Y4: =IF(H4>J4,1,0) -> 0 | Z4: =IF(X4+Y4=2,5,0) -> 0 | AA4: =IF(H4="n",0,Z4) -> 0 | AB4: =IF(Q4=5,0,AA4) -> 0 | AD4: =IF(D4<F4,1,0) -> 1 | AE4: =IF(H4<J4,1,0) -> 1 | AF4: =IF(AD4+AE4=2,5,0) -> 5 | AG4: =IF(Q4=5,0,AF4) -> 5
A5: =TABELA!A5 -> 46202 | B5: =TABELA!B5 -> 0.58333333 | C5: =TABELA!C5 -> Brasil | D5: 2 | E5: x | F5: 2 | G5: =TABELA!G5 -> Japão | H5: =TABELA!D5 -> 2 | I5: x | J5: =TABELA!F5 -> 1 | K5: =O5+P5+U5+AA5+AF5 -> 2 | O5: =IF(D5=H5,2,0) -> 2 | P5: =IF(F5=J5,2,0) -> 0 | Q5: =IF(O5+P5=4,5,0) -> 0 | S5: =IF(D5=F5,1,0) -> 1 | T5: =IF(H5=J5,1,0) -> 0 | U5: =IF(S5+T5=2,5,0) -> 0 | V5: =IF(Q5=5,0,U5) -> 0 | X5: =IF(D5>F5,1,0) -> 0 | Y5: =IF(H5>J5,1,0) -> 1 | Z5: =IF(X5+Y5=2,5,0) -> 0 | AA5: =IF(H5="n",0,Z5) -> 0 | AB5: =IF(Q5=5,0,AA5) -> 0 | AD5: =IF(D5<F5,1,0) -> 0 | AE5: =IF(H5<J5,1,0) -> 0 | AF5: =IF(AD5+AE5=2,5,0) -> 0 | AG5: =IF(Q5=5,0,AF5) -> 0
A6: =TABELA!A6 -> 46202 | B6: =TABELA!B6 -> 0.72916667 | C6: =TABELA!C6 -> Alemanha | D6: 3 | E6: x | F6: 0 | G6: =TABELA!G6 -> Paraguai | H6: =TABELA!D6 -> 1 | I6: x | J6: =TABELA!F6 -> 1 | K6: =O6+P6+U6+AA6+AF6 -> 0 | O6: =IF(D6=H6,2,0) -> 0 | P6: =IF(F6=J6,2,0) -> 0 | Q6: =IF(O6+P6=4,5,0) -> 0 | S6: =IF(D6=F6,1,0) -> 0 | T6: =IF(H6=J6,1,0) -> 1 | U6: =IF(S6+T6=2,5,0) -> 0 | V6: =IF(Q6=5,0,U6) -> 0 | X6: =IF(D6>F6,1,0) -> 1 | Y6: =IF(H6>J6,1,0) -> 0 | Z6: =IF(X6+Y6=2,5,0) -> 0 | AA6: =IF(H6="n",0,Z6) -> 0 | AB6: =IF(Q6=5,0,AA6) -> 0 | AD6: =IF(D6<F6,1,0) -> 0 | AE6: =IF(H6<J6,1,0) -> 0 | AF6: =IF(AD6+AE6=2,5,0) -> 0 | AG6: =IF(Q6=5,0,AF6) -> 0
A7: =TABELA!A7 -> 46202 | B7: =TABELA!B7 -> 0.91666667 | C7: =TABELA!C7 -> Holanda | D7: 3 | E7: x | F7: 1 | G7: =TABELA!G7 -> Marrocos | H7: =TABELA!D7 -> 1 | I7: x | J7: =TABELA!F7 -> 1 | K7: =O7+P7+U7+AA7+AF7 -> 2 | O7: =IF(D7=H7,2,0) -> 0 | P7: =IF(F7=J7,2,0) -> 2 | Q7: =IF(O7+P7=4,5,0) -> 0 | S7: =IF(D7=F7,1,0) -> 0 | T7: =IF(H7=J7,1,0) -> 1 | U7: =IF(S7+T7=2,5,0) -> 0 | V7: =IF(Q7=5,0,U7) -> 0 | X7: =IF(D7>F7,1,0) -> 1 | Y7: =IF(H7>J7,1,0) -> 0 | Z7: =IF(X7+Y7=2,5,0) -> 0 | AA7: =IF(H7="n",0,Z7) -> 0 | AB7: =IF(Q7=5,0,AA7) -> 0 | AD7: =IF(D7<F7,1,0) -> 0 | AE7: =IF(H7<J7,1,0) -> 0 | AF7: =IF(AD7+AE7=2,5,0) -> 0 | AG7: =IF(Q7=5,0,AF7) -> 0
A8: =TABELA!A8 -> 46203 | B8: =TABELA!B8 -> 0.58333333 | C8: =TABELA!C8 -> Cost. do Marf. | D8: 1 | E8: x | F8: 2 | G8: =TABELA!G8 -> Noruega | H8: =TABELA!D8 -> n | I8: x | J8: =TABELA!F8 -> d | K8: =O8+P8+U8+AA8+AF8 -> 0 | O8: =IF(D8=H8,2,0) -> 0 | P8: =IF(F8=J8,2,0) -> 0 | Q8: =IF(O8+P8=4,5,0) -> 0 | S8: =IF(D8=F8,1,0) -> 0 | T8: =IF(H8=J8,1,0) -> 0 | U8: =IF(S8+T8=2,5,0) -> 0 | V8: =IF(Q8=5,0,U8) -> 0 | X8: =IF(D8>F8,1,0) -> 0 | Y8: =IF(H8>J8,1,0) -> 1 | Z8: =IF(X8+Y8=2,5,0) -> 0 | AA8: =IF(H8="n",0,Z8) -> 0 | AB8: =IF(Q8=5,0,AA8) -> 0 | AD8: =IF(D8<F8,1,0) -> 1 | AE8: =IF(H8<J8,1,0) -> 0 | AF8: =IF(AD8+AE8=2,5,0) -> 0 | AG8: =IF(Q8=5,0,AF8) -> 0
A9: =TABELA!A9 -> 46203 | B9: =TABELA!B9 -> 0.75 | C9: =TABELA!C9 -> França | D9: 3 | E9: x | F9: 0 | G9: =TABELA!G9 -> Suécia | H9: =TABELA!D9 -> n | I9: x | J9: =TABELA!F9 -> d | K9: =O9+P9+U9+AA9+AF9 -> 0 | O9: =IF(D9=H9,2,0) -> 0 | P9: =IF(F9=J9,2,0) -> 0 | Q9: =IF(O9+P9=4,5,0) -> 0 | S9: =IF(D9=F9,1,0) -> 0 | T9: =IF(H9=J9,1,0) -> 0 | U9: =IF(S9+T9=2,5,0) -> 0 | V9: =IF(Q9=5,0,U9) -> 0 | X9: =IF(D9>F9,1,0) -> 1 | Y9: =IF(H9>J9,1,0) -> 1 | Z9: =IF(X9+Y9=2,5,0) -> 5 | AA9: =IF(H9="n",0,Z9) -> 0 | AB9: =IF(Q9=5,0,AA9) -> 0 | AD9: =IF(D9<F9,1,0) -> 0 | AE9: =IF(H9<J9,1,0) -> 0 | AF9: =IF(AD9+AE9=2,5,0) -> 0 | AG9: =IF(Q9=5,0,AF9) -> 0
A11: =TABELA!A11 -> 46203 | B11: =TABELA!B11 -> 0.91666667 | C11: =TABELA!C11 -> México | D11: 2 | E11: x | F11: 1 | G11: =TABELA!G11 -> Equador | H11: =TABELA!D11 -> n | I11: x | J11: =TABELA!F11 -> d | K11: =O11+P11+U11+AA11+AF11 -> 0 | L11: B | O11: =IF(D11=H11,2,0) -> 0 | P11: =IF(F11=J11,2,0) -> 0 | Q11: =IF(O11+P11=4,5,0) -> 0 | S11: =IF(D11=F11,1,0) -> 0 | T11: =IF(H11=J11,1,0) -> 0 | U11: =IF(S11+T11=2,5,0) -> 0 | V11: =IF(Q11=5,0,U11) -> 0 | X11: =IF(D11>F11,1,0) -> 1 | Y11: =IF(H11>J11,1,0) -> 1 | Z11: =IF(X11+Y11=2,5,0) -> 5 | AA11: =IF(H11="n",0,Z11) -> 0 | AB11: =IF(Q11=5,0,AA11) -> 0 | AD11: =IF(D11<F11,1,0) -> 0 | AE11: =IF(H11<J11,1,0) -> 0 | AF11: =IF(AD11+AE11=2,5,0) -> 0 | AG11: =IF(Q11=5,0,AF11) -> 0
A12: =TABELA!A12 -> 46204 | B12: =TABELA!B12 -> 0.54166667 | C12: =TABELA!C12 -> Inglaterra | D12: 3 | E12: x | F12: 1 | G12: =TABELA!G12 -> Congo | H12: =TABELA!D12 -> n | I12: x | J12: =TABELA!F12 -> d | K12: =O12+P12+U12+AA12+AF12 -> 0 | O12: =IF(D12=H12,2,0) -> 0 | P12: =IF(F12=J12,2,0) -> 0 | Q12: =IF(O12+P12=4,5,0) -> 0 | S12: =IF(D12=F12,1,0) -> 0 | T12: =IF(H12=J12,1,0) -> 0 | U12: =IF(S12+T12=2,5,0) -> 0 | V12: =IF(Q12=5,0,U12) -> 0 | X12: =IF(D12>F12,1,0) -> 1 | Y12: =IF(H12>J12,1,0) -> 1 | Z12: =IF(X12+Y12=2,5,0) -> 5 | AA12: =IF(H12="n",0,Z12) -> 0 | AB12: =IF(Q12=5,0,AA12) -> 0 | AD12: =IF(D12<F12,1,0) -> 0 | AE12: =IF(H12<J12,1,0) -> 0 | AF12: =IF(AD12+AE12=2,5,0) -> 0 | AG12: =IF(Q12=5,0,AF12) -> 0
A13: =TABELA!A13 -> 46204 | B13: =TABELA!B13 -> 0.70833333 | C13: =TABELA!C13 -> Bélgica | D13: 2 | E13: x | F13: 1 | G13: =TABELA!G13 -> Senegal | H13: =TABELA!D13 -> n | I13: x | J13: =TABELA!F13 -> d | K13: =O13+P13+U13+AA13+AF13 -> 0 | O13: =IF(D13=H13,2,0) -> 0 | P13: =IF(F13=J13,2,0) -> 0 | Q13: =IF(O13+P13=4,5,0) -> 0 | S13: =IF(D13=F13,1,0) -> 0 | T13: =IF(H13=J13,1,0) -> 0 | U13: =IF(S13+T13=2,5,0) -> 0 | V13: =IF(Q13=5,0,U13) -> 0 | X13: =IF(D13>F13,1,0) -> 1 | Y13: =IF(H13>J13,1,0) -> 1 | Z13: =IF(X13+Y13=2,5,0) -> 5 | AA13: =IF(H13="n",0,Z13) -> 0 | AB13: =IF(Q13=5,0,AA13) -> 0 | AD13: =IF(D13<F13,1,0) -> 0 | AE13: =IF(H13<J13,1,0) -> 0 | AF13: =IF(AD13+AE13=2,5,0) -> 0 | AG13: =IF(Q13=5,0,AF13) -> 0
A14: =TABELA!A14 -> 46204 | B14: =TABELA!B14 -> 0.875 | C14: =TABELA!C14 -> Estados Unidos | D14: 4 | E14: x | F14: 1 | G14: =TABELA!G14 -> Bósnia | H14: =TABELA!D14 -> n | I14: x | J14: =TABELA!F14 -> d | K14: =O14+P14+U14+AA14+AF14 -> 0 | O14: =IF(D14=H14,2,0) -> 0 | P14: =IF(F14=J14,2,0) -> 0 | Q14: =IF(O14+P14=4,5,0) -> 0 | S14: =IF(D14=F14,1,0) -> 0 | T14: =IF(H14=J14,1,0) -> 0 | U14: =IF(S14+T14=2,5,0) -> 0 | V14: =IF(Q14=5,0,U14) -> 0 | X14: =IF(D14>F14,1,0) -> 1 | Y14: =IF(H14>J14,1,0) -> 1 | Z14: =IF(X14+Y14=2,5,0) -> 5 | AA14: =IF(H14="n",0,Z14) -> 0 | AB14: =IF(Q14=5,0,AA14) -> 0 | AD14: =IF(D14<F14,1,0) -> 0 | AE14: =IF(H14<J14,1,0) -> 0 | AF14: =IF(AD14+AE14=2,5,0) -> 0 | AG14: =IF(Q14=5,0,AF14) -> 0
A15: =TABELA!A15 -> 46205 | B15: =TABELA!B15 -> 0.66666667 | C15: Espanha | D15: 4 | E15: x | F15: 1 | G15: =TABELA!G15 -> Áustria | H15: =TABELA!D15 -> n | I15: x | J15: =TABELA!F15 -> d | K15: =O15+P15+U15+AA15+AF15 -> 0 | O15: =IF(D15=H15,2,0) -> 0 | P15: =IF(F15=J15,2,0) -> 0 | Q15: =IF(O15+P15=4,5,0) -> 0 | S15: =IF(D15=F15,1,0) -> 0 | T15: =IF(H15=J15,1,0) -> 0 | U15: =IF(S15+T15=2,5,0) -> 0 | V15: =IF(Q15=5,0,U15) -> 0 | X15: =IF(D15>F15,1,0) -> 1 | Y15: =IF(H15>J15,1,0) -> 1 | Z15: =IF(X15+Y15=2,5,0) -> 5 | AA15: =IF(H15="n",0,Z15) -> 0 | AB15: =IF(Q15=5,0,AA15) -> 0 | AD15: =IF(D15<F15,1,0) -> 0 | AE15: =IF(H15<J15,1,0) -> 0 | AF15: =IF(AD15+AE15=2,5,0) -> 0 | AG15: =IF(Q15=5,0,AF15) -> 0
A16: =TABELA!A16 -> 46205 | B16: =TABELA!B16 -> 0.83333333 | C16: =TABELA!C16 -> Portugal | D16: 3 | E16: x | F16: 1 | G16: =TABELA!G16 -> Croácia | H16: =TABELA!D16 -> n | I16: x | J16: =TABELA!F16 -> d | K16: =O16+P16+U16+AA16+AF16 -> 0 | O16: =IF(D16=H16,2,0) -> 0 | P16: =IF(F16=J16,2,0) -> 0 | Q16: =IF(O16+P16=4,5,0) -> 0 | S16: =IF(D16=F16,1,0) -> 0 | T16: =IF(H16=J16,1,0) -> 0 | U16: =IF(S16+T16=2,5,0) -> 0 | V16: =IF(Q16=5,0,U16) -> 0 | X16: =IF(D16>F16,1,0) -> 1 | Y16: =IF(H16>J16,1,0) -> 1 | Z16: =IF(X16+Y16=2,5,0) -> 5 | AA16: =IF(H16="n",0,Z16) -> 0 | AB16: =IF(Q16=5,0,AA16) -> 0 | AD16: =IF(D16<F16,1,0) -> 0 | AE16: =IF(H16<J16,1,0) -> 0 | AF16: =IF(AD16+AE16=2,5,0) -> 0 | AG16: =IF(Q16=5,0,AF16) -> 0
A18: =TABELA!A18 -> 46206 | B18: =TABELA!B18 -> 0 | C18: =TABELA!C18 -> Suíça | D18: 3 | E18: x | F18: 0 | G18: =TABELA!G18 -> Argélia | H18: =TABELA!D18 -> n | I18: x | J18: =TABELA!F18 -> d | K18: =O18+P18+U18+AA18+AF18 -> 0 | L18: C | O18: =IF(D18=H18,2,0) -> 0 | P18: =IF(F18=J18,2,0) -> 0 | Q18: =IF(O18+P18=4,5,0) -> 0 | S18: =IF(D18=F18,1,0) -> 0 | T18: =IF(H18=J18,1,0) -> 0 | U18: =IF(S18+T18=2,5,0) -> 0 | V18: =IF(Q18=5,0,U18) -> 0 | X18: =IF(D18>F18,1,0) -> 1 | Y18: =IF(H18>J18,1,0) -> 1 | Z18: =IF(X18+Y18=2,5,0) -> 5 | AA18: =IF(H18="n",0,Z18) -> 0 | AB18: =IF(Q18=5,0,AA18) -> 0 | AD18: =IF(D18<F18,1,0) -> 0 | AE18: =IF(H18<J18,1,0) -> 0 | AF18: =IF(AD18+AE18=2,5,0) -> 0 | AG18: =IF(Q18=5,0,AF18) -> 0
A20: =TABELA!A20 -> 46206 | B20: =TABELA!B20 -> 0.625 | C20: =TABELA!C20 -> Austrália | D20: 0 | E20: x | F20: 2 | G20: =TABELA!G20 -> Egito | H20: =TABELA!D20 -> n | I20: x | J20: =TABELA!F20 -> d | K20: =O20+P20+U20+AA20+AF20 -> 0 | O20: =IF(D20=H20,2,0) -> 0 | P20: =IF(F20=J20,2,0) -> 0 | Q20: =IF(O20+P20=4,5,0) -> 0 | S20: =IF(D20=F20,1,0) -> 0 | T20: =IF(H20=J20,1,0) -> 0 | U20: =IF(S20+T20=2,5,0) -> 0 | V20: =IF(Q20=5,0,U20) -> 0 | X20: =IF(D20>F20,1,0) -> 0 | Y20: =IF(H20>J20,1,0) -> 1 | Z20: =IF(X20+Y20=2,5,0) -> 0 | AA20: =IF(H20="n",0,Z20) -> 0 | AB20: =IF(Q20=5,0,AA20) -> 0 | AD20: =IF(D20<F20,1,0) -> 1 | AE20: =IF(H20<J20,1,0) -> 0 | AF20: =IF(AD20+AE20=2,5,0) -> 0 | AG20: =IF(Q20=5,0,AF20) -> 0
A22: =TABELA!A22 -> 46206 | B22: =TABELA!B22 -> 0.79166667 | C22: =TABELA!C22 -> Argentina | D22: 3 | E22: x | F22: 0 | G22: =TABELA!G22 -> Cabo Verde | H22: =TABELA!D22 -> n | I22: x | J22: =TABELA!F22 -> d | K22: =O22+P22+U22+AA22+AF22 -> 0 | O22: =IF(D22=H22,2,0) -> 0 | P22: =IF(F22=J22,2,0) -> 0 | Q22: =IF(O22+P22=4,5,0) -> 0 | S22: =IF(D22=F22,1,0) -> 0 | T22: =IF(H22=J22,1,0) -> 0 | U22: =IF(S22+T22=2,5,0) -> 0 | V22: =IF(Q22=5,0,U22) -> 0 | X22: =IF(D22>F22,1,0) -> 1 | Y22: =IF(H22>J22,1,0) -> 1 | Z22: =IF(X22+Y22=2,5,0) -> 5 | AA22: =IF(H22="n",0,Z22) -> 0 | AB22: =IF(Q22=5,0,AA22) -> 0 | AD22: =IF(D22<F22,1,0) -> 0 | AE22: =IF(H22<J22,1,0) -> 0 | AF22: =IF(AD22+AE22=2,5,0) -> 0 | AG22: =IF(Q22=5,0,AF22) -> 0
A24: =TABELA!A24 -> 46206 | B24: =TABELA!B24 -> 0.9375 | C24: Colômbia | D24: 1 | E24: x | F24: 1 | G24: Gana | H24: =TABELA!D24 -> n | I24: x | J24: =TABELA!F24 -> d | K24: =O24+P24+U24+AA24+AF24 -> 0 | O24: =IF(D24=H24,2,0) -> 0 | P24: =IF(F24=J24,2,0) -> 0 | Q24: =IF(O24+P24=4,5,0) -> 0 | S24: =IF(D24=F24,1,0) -> 1 | T24: =IF(H24=J24,1,0) -> 0 | U24: =IF(S24+T24=2,5,0) -> 0 | V24: =IF(Q24=5,0,U24) -> 0 | X24: =IF(D24>F24,1,0) -> 0 | Y24: =IF(H24>J24,1,0) -> 1 | Z24: =IF(X24+Y24=2,5,0) -> 0 | AA24: =IF(H24="n",0,Z24) -> 0 | AB24: =IF(Q24=5,0,AA24) -> 0 | AD24: =IF(D24<F24,1,0) -> 0 | AE24: =IF(H24<J24,1,0) -> 0 | AF24: =IF(AD24+AE24=2,5,0) -> 0 | AG24: =IF(Q24=5,0,AF24) -> 0
A26: 46207 | B26: 0.58333333 | E26: x | H26: n | I26: x | J26: d | K26: =O26+P26+U26+AA26+AF26 -> 0 | O26: =IF(D26=H26,2,0) -> 0 | P26: =IF(F26=J26,2,0) -> 0 | Q26: =IF(O26+P26=4,5,0) -> 0 | S26: =IF(D26=F26,1,0) -> 1 | T26: =IF(H26=J26,1,0) -> 0 | U26: =IF(S26+T26=2,5,0) -> 0 | V26: =IF(Q26=5,0,U26) -> 0 | X26: =IF(D26>F26,1,0) -> 0 | Y26: =IF(H26>J26,1,0) -> 1 | Z26: =IF(X26+Y26=2,5,0) -> 0 | AA26: =IF(H26="n",0,Z26) -> 0 | AB26: =IF(Q26=5,0,AA26) -> 0 | AD26: =IF(D26<F26,1,0) -> 0 | AE26: =IF(H26<J26,1,0) -> 0 | AF26: =IF(AD26+AE26=2,5,0) -> 0 | AG26: =IF(Q26=5,0,AF26) -> 0
A28: 46207 | B28: 0.75 | E28: x | H28: n | I28: x | J28: d | K28: =O28+P28+U28+AA28+AF28 -> 0 | O28: =IF(D28=H28,2,0) -> 0 | P28: =IF(F28=J28,2,0) -> 0 | Q28: =IF(O28+P28=4,5,0) -> 0 | S28: =IF(D28=F28,1,0) -> 1 | T28: =IF(H28=J28,1,0) -> 0 | U28: =IF(S28+T28=2,5,0) -> 0 | V28: =IF(Q28=5,0,U28) -> 0 | X28: =IF(D28>F28,1,0) -> 0 | Y28: =IF(H28>J28,1,0) -> 1 | Z28: =IF(X28+Y28=2,5,0) -> 0 | AA28: =IF(H28="n",0,Z28) -> 0 | AB28: =IF(Q28=5,0,AA28) -> 0 | AD28: =IF(D28<F28,1,0) -> 0 | AE28: =IF(H28<J28,1,0) -> 0 | AF28: =IF(AD28+AE28=2,5,0) -> 0 | AG28: =IF(Q28=5,0,AF28) -> 0
A31: 46208 | B31: 0.70833333 | E31: x | H31: n | I31: x | J31: d | K31: =O31+P31+U31+AA31+AF31 -> 0 | L31: D | O31: =IF(D31=H31,2,0) -> 0 | P31: =IF(F31=J31,2,0) -> 0 | Q31: =IF(O31+P31=4,5,0) -> 0 | S31: =IF(D31=F31,1,0) -> 1 | T31: =IF(H31=J31,1,0) -> 0 | U31: =IF(S31+T31=2,5,0) -> 0 | V31: =IF(Q31=5,0,U31) -> 0 | X31: =IF(D31>F31,1,0) -> 0 | Y31: =IF(H31>J31,1,0) -> 1 | Z31: =IF(X31+Y31=2,5,0) -> 0 | AA31: =IF(H31="n",0,Z31) -> 0 | AB31: =IF(Q31=5,0,AA31) -> 0 | AD31: =IF(D31<F31,1,0) -> 0 | AE31: =IF(H31<J31,1,0) -> 0 | AF31: =IF(AD31+AE31=2,5,0) -> 0 | AG31: =IF(Q31=5,0,AF31) -> 0
A33: 46208 | B33: 0.875 | E33: x | H33: n | I33: x | J33: d | K33: =O33+P33+U33+AA33+AF33 -> 0 | O33: =IF(D33=H33,2,0) -> 0 | P33: =IF(F33=J33,2,0) -> 0 | Q33: =IF(O33+P33=4,5,0) -> 0 | S33: =IF(D33=F33,1,0) -> 1 | T33: =IF(H33=J33,1,0) -> 0 | U33: =IF(S33+T33=2,5,0) -> 0 | V33: =IF(Q33=5,0,U33) -> 0 | X33: =IF(D33>F33,1,0) -> 0 | Y33: =IF(H33>J33,1,0) -> 1 | Z33: =IF(X33+Y33=2,5,0) -> 0 | AA33: =IF(H33="n",0,Z33) -> 0 | AB33: =IF(Q33=5,0,AA33) -> 0 | AD33: =IF(D33<F33,1,0) -> 0 | AE33: =IF(H33<J33,1,0) -> 0 | AF33: =IF(AD33+AE33=2,5,0) -> 0 | AG33: =IF(Q33=5,0,AF33) -> 0
A35: 46209 | B35: 0.66666667 | E35: x | H35: n | I35: x | J35: d | K35: =O35+P35+U35+AA35+AF35 -> 0 | O35: =IF(D35=H35,2,0) -> 0 | P35: =IF(F35=J35,2,0) -> 0 | Q35: =IF(O35+P35=4,5,0) -> 0 | S35: =IF(D35=F35,1,0) -> 1 | T35: =IF(H35=J35,1,0) -> 0 | U35: =IF(S35+T35=2,5,0) -> 0 | V35: =IF(Q35=5,0,U35) -> 0 | X35: =IF(D35>F35,1,0) -> 0 | Y35: =IF(H35>J35,1,0) -> 1 | Z35: =IF(X35+Y35=2,5,0) -> 0 | AA35: =IF(H35="n",0,Z35) -> 0 | AB35: =IF(Q35=5,0,AA35) -> 0 | AD35: =IF(D35<F35,1,0) -> 0 | AE35: =IF(H35<J35,1,0) -> 0 | AF35: =IF(AD35+AE35=2,5,0) -> 0 | AG35: =IF(Q35=5,0,AF35) -> 0
A37: 46209 | B37: 0.875 | E37: x | H37: n | I37: x | J37: d | K37: =O37+P37+U37+AA37+AF37 -> 0 | O37: =IF(D37=H37,2,0) -> 0 | P37: =IF(F37=J37,2,0) -> 0 | Q37: =IF(O37+P37=4,5,0) -> 0 | S37: =IF(D37=F37,1,0) -> 1 | T37: =IF(H37=J37,1,0) -> 0 | U37: =IF(S37+T37=2,5,0) -> 0 | V37: =IF(Q37=5,0,U37) -> 0 | X37: =IF(D37>F37,1,0) -> 0 | Y37: =IF(H37>J37,1,0) -> 1 | Z37: =IF(X37+Y37=2,5,0) -> 0 | AA37: =IF(H37="n",0,Z37) -> 0 | AB37: =IF(Q37=5,0,AA37) -> 0 | AD37: =IF(D37<F37,1,0) -> 0 | AE37: =IF(H37<J37,1,0) -> 0 | AF37: =IF(AD37+AE37=2,5,0) -> 0 | AG37: =IF(Q37=5,0,AF37) -> 0
A39: 46210 | B39: 0.54166667 | E39: x | H39: n | I39: x | J39: d | K39: =O39+P39+U39+AA39+AF39 -> 0 | O39: =IF(D39=H39,2,0) -> 0 | P39: =IF(F39=J39,2,0) -> 0 | Q39: =IF(O39+P39=4,5,0) -> 0 | S39: =IF(D39=F39,1,0) -> 1 | T39: =IF(H39=J39,1,0) -> 0 | U39: =IF(S39+T39=2,5,0) -> 0 | V39: =IF(Q39=5,0,U39) -> 0 | X39: =IF(D39>F39,1,0) -> 0 | Y39: =IF(H39>J39,1,0) -> 1 | Z39: =IF(X39+Y39=2,5,0) -> 0 | AA39: =IF(H39="n",0,Z39) -> 0 | AB39: =IF(Q39=5,0,AA39) -> 0 | AD39: =IF(D39<F39,1,0) -> 0 | AE39: =IF(H39<J39,1,0) -> 0 | AF39: =IF(AD39+AE39=2,5,0) -> 0 | AG39: =IF(Q39=5,0,AF39) -> 0
A41: 46210 | B41: 0.70833333 | E41: x | H41: n | I41: x | J41: d | K41: =O41+P41+U41+AA41+AF41 -> 0 | O41: =IF(D41=H41,2,0) -> 0 | P41: =IF(F41=J41,2,0) -> 0 | Q41: =IF(O41+P41=4,5,0) -> 0 | S41: =IF(D41=F41,1,0) -> 1 | T41: =IF(H41=J41,1,0) -> 0 | U41: =IF(S41+T41=2,5,0) -> 0 | V41: =IF(Q41=5,0,U41) -> 0 | X41: =IF(D41>F41,1,0) -> 0 | Y41: =IF(H41>J41,1,0) -> 1 | Z41: =IF(X41+Y41=2,5,0) -> 0 | AA41: =IF(H41="n",0,Z41) -> 0 | AB41: =IF(Q41=5,0,AA41) -> 0 | AD41: =IF(D41<F41,1,0) -> 0 | AE41: =IF(H41<J41,1,0) -> 0 | AF41: =IF(AD41+AE41=2,5,0) -> 0 | AG41: =IF(Q41=5,0,AF41) -> 0
A44: 46212 | B44: 0.70833333 | E44: x | H44: n | I44: x | J44: d | K44: =O44+P44+U44+AA44+AF44 -> 0 | L44: E | O44: =IF(D44=H44,2,0) -> 0 | P44: =IF(F44=J44,2,0) -> 0 | Q44: =IF(O44+P44=4,5,0) -> 0 | S44: =IF(D44=F44,1,0) -> 1 | T44: =IF(H44=J44,1,0) -> 0 | U44: =IF(S44+T44=2,5,0) -> 0 | V44: =IF(Q44=5,0,U44) -> 0 | X44: =IF(D44>F44,1,0) -> 0 | Y44: =IF(H44>J44,1,0) -> 1 | Z44: =IF(X44+Y44=2,5,0) -> 0 | AA44: =IF(H44="n",0,Z44) -> 0 | AB44: =IF(Q44=5,0,AA44) -> 0 | AD44: =IF(D44<F44,1,0) -> 0 | AE44: =IF(H44<J44,1,0) -> 0 | AF44: =IF(AD44+AE44=2,5,0) -> 0 | AG44: =IF(Q44=5,0,AF44) -> 0
A46: 46213 | B46: 0.66666667 | E46: x | H46: n | I46: x | J46: d | K46: =O46+P46+U46+AA46+AF46 -> 0 | O46: =IF(D46=H46,2,0) -> 0 | P46: =IF(F46=J46,2,0) -> 0 | Q46: =IF(O46+P46=4,5,0) -> 0 | S46: =IF(D46=F46,1,0) -> 1 | T46: =IF(H46=J46,1,0) -> 0 | U46: =IF(S46+T46=2,5,0) -> 0 | V46: =IF(Q46=5,0,U46) -> 0 | X46: =IF(D46>F46,1,0) -> 0 | Y46: =IF(H46>J46,1,0) -> 1 | Z46: =IF(X46+Y46=2,5,0) -> 0 | AA46: =IF(H46="n",0,Z46) -> 0 | AB46: =IF(Q46=5,0,AA46) -> 0 | AD46: =IF(D46<F46,1,0) -> 0 | AE46: =IF(H46<J46,1,0) -> 0 | AF46: =IF(AD46+AE46=2,5,0) -> 0 | AG46: =IF(Q46=5,0,AF46) -> 0
A48: 46214 | B48: 0.75 | E48: x | H48: n | I48: x | J48: d | K48: =O48+P48+U48+AA48+AF48 -> 0 | O48: =IF(D48=H48,2,0) -> 0 | P48: =IF(F48=J48,2,0) -> 0 | Q48: =IF(O48+P48=4,5,0) -> 0 | S48: =IF(D48=F48,1,0) -> 1 | T48: =IF(H48=J48,1,0) -> 0 | U48: =IF(S48+T48=2,5,0) -> 0 | V48: =IF(Q48=5,0,U48) -> 0 | X48: =IF(D48>F48,1,0) -> 0 | Y48: =IF(H48>J48,1,0) -> 1 | Z48: =IF(X48+Y48=2,5,0) -> 0 | AA48: =IF(H48="n",0,Z48) -> 0 | AB48: =IF(Q48=5,0,AA48) -> 0 | AD48: =IF(D48<F48,1,0) -> 0 | AE48: =IF(H48<J48,1,0) -> 0 | AF48: =IF(AD48+AE48=2,5,0) -> 0 | AG48: =IF(Q48=5,0,AF48) -> 0
A50: 46214 | B50: 0.91666667 | E50: x | H50: n | I50: x | J50: d | K50: =O50+P50+U50+AA50+AF50 -> 0 | O50: =IF(D50=H50,2,0) -> 0 | P50: =IF(F50=J50,2,0) -> 0 | Q50: =IF(O50+P50=4,5,0) -> 0 | S50: =IF(D50=F50,1,0) -> 1 | T50: =IF(H50=J50,1,0) -> 0 | U50: =IF(S50+T50=2,5,0) -> 0 | V50: =IF(Q50=5,0,U50) -> 0 | X50: =IF(D50>F50,1,0) -> 0 | Y50: =IF(H50>J50,1,0) -> 1 | Z50: =IF(X50+Y50=2,5,0) -> 0 | AA50: =IF(H50="n",0,Z50) -> 0 | AB50: =IF(Q50=5,0,AA50) -> 0 | AD50: =IF(D50<F50,1,0) -> 0 | AE50: =IF(H50<J50,1,0) -> 0 | AF50: =IF(AD50+AE50=2,5,0) -> 0 | AG50: =IF(Q50=5,0,AF50) -> 0
A52: 46217 | B52: 0.66666667 | E52: x | H52: n | I52: x | J52: d | K52: =O52+P52+U52+AA52+AF52 -> 0 | O52: =IF(D52=H52,2,0) -> 0 | P52: =IF(F52=J52,2,0) -> 0 | Q52: =IF(O52+P52=4,5,0) -> 0 | S52: =IF(D52=F52,1,0) -> 1 | T52: =IF(H52=J52,1,0) -> 0 | U52: =IF(S52+T52=2,5,0) -> 0 | V52: =IF(Q52=5,0,U52) -> 0 | X52: =IF(D52>F52,1,0) -> 0 | Y52: =IF(H52>J52,1,0) -> 1 | Z52: =IF(X52+Y52=2,5,0) -> 0 | AA52: =IF(H52="n",0,Z52) -> 0 | AB52: =IF(Q52=5,0,AA52) -> 0 | AD52: =IF(D52<F52,1,0) -> 0 | AE52: =IF(H52<J52,1,0) -> 0 | AF52: =IF(AD52+AE52=2,5,0) -> 0 | AG52: =IF(Q52=5,0,AF52) -> 0
A54: 46218 | B54: 0.66666667 | E54: x | H54: n | I54: x | J54: d | K54: =O54+P54+U54+AA54+AF54 -> 0 | O54: =IF(D54=H54,2,0) -> 0 | P54: =IF(F54=J54,2,0) -> 0 | Q54: =IF(O54+P54=4,5,0) -> 0 | S54: =IF(D54=F54,1,0) -> 1 | T54: =IF(H54=J54,1,0) -> 0 | U54: =IF(S54+T54=2,5,0) -> 0 | V54: =IF(Q54=5,0,U54) -> 0 | X54: =IF(D54>F54,1,0) -> 0 | Y54: =IF(H54>J54,1,0) -> 1 | Z54: =IF(X54+Y54=2,5,0) -> 0 | AA54: =IF(H54="n",0,Z54) -> 0 | AB54: =IF(Q54=5,0,AA54) -> 0 | AD54: =IF(D54<F54,1,0) -> 0 | AE54: =IF(H54<J54,1,0) -> 0 | AF54: =IF(AD54+AE54=2,5,0) -> 0 | AG54: =IF(Q54=5,0,AF54) -> 0
A57: 46221 | B57: 0.75 | E57: x | H57: n | I57: x | J57: d | K57: =O57+P57+U57+AA57+AF57 -> 0 | L57: F | O57: =IF(D57=H57,2,0) -> 0 | P57: =IF(F57=J57,2,0) -> 0 | Q57: =IF(O57+P57=4,5,0) -> 0 | S57: =IF(D57=F57,1,0) -> 1 | T57: =IF(H57=J57,1,0) -> 0 | U57: =IF(S57+T57=2,5,0) -> 0 | V57: =IF(Q57=5,0,U57) -> 0 | X57: =IF(D57>F57,1,0) -> 0 | Y57: =IF(H57>J57,1,0) -> 1 | Z57: =IF(X57+Y57=2,5,0) -> 0 | AA57: =IF(H57="n",0,Z57) -> 0 | AB57: =IF(Q57=5,0,AA57) -> 0 | AD57: =IF(D57<F57,1,0) -> 0 | AE57: =IF(H57<J57,1,0) -> 0 | AF57: =IF(AD57+AE57=2,5,0) -> 0 | AG57: =IF(Q57=5,0,AF57) -> 0
A59: 46222 | B59: 0.66666667 | E59: x | H59: n | I59: x | J59: d | K59: =O59+P59+U59+AA59+AF59 -> 0 | O59: =IF(D59=H59,2,0) -> 0 | P59: =IF(F59=J59,2,0) -> 0 | Q59: =IF(O59+P59=4,5,0) -> 0 | S59: =IF(D59=F59,1,0) -> 1 | T59: =IF(H59=J59,1,0) -> 0 | U59: =IF(S59+T59=2,5,0) -> 0 | V59: =IF(Q59=5,0,U59) -> 0 | X59: =IF(D59>F59,1,0) -> 0 | Y59: =IF(H59>J59,1,0) -> 1 | Z59: =IF(X59+Y59=2,5,0) -> 0 | AA59: =IF(H59="n",0,Z59) -> 0 | AB59: =IF(Q59=5,0,AA59) -> 0 | AD59: =IF(D59<F59,1,0) -> 0 | AE59: =IF(H59<J59,1,0) -> 0 | AF59: =IF(AD59+AE59=2,5,0) -> 0 | AG59: =IF(Q59=5,0,AF59) -> 0
E61: x | H61: n | I61: x | J61: d | K61: =O61+P61+U61+AA61+AF61 -> 0 | O61: =IF(D61=H61,2,0) -> 0 | P61: =IF(F61=J61,2,0) -> 0 | Q61: =IF(O61+P61=4,5,0) -> 0 | S61: =IF(D61=F61,1,0) -> 1 | T61: =IF(H61=J61,1,0) -> 0 | U61: =IF(S61+T61=2,5,0) -> 0 | V61: =IF(Q61=5,0,U61) -> 0 | X61: =IF(D61>F61,1,0) -> 0 | Y61: =IF(H61>J61,1,0) -> 1 | Z61: =IF(X61+Y61=2,5,0) -> 0 | AA61: =IF(H61="n",0,Z61) -> 0 | AB61: =IF(Q61=5,0,AA61) -> 0 | AD61: =IF(D61<F61,1,0) -> 0 | AE61: =IF(H61<J61,1,0) -> 0 | AF61: =IF(AD61+AE61=2,5,0) -> 0 | AG61: =IF(Q61=5,0,AF61) -> 0
E63: x | H63: n | I63: x | J63: d | K63: =O63+P63+U63+AA63+AF63 -> 0 | O63: =IF(D63=H63,2,0) -> 0 | P63: =IF(F63=J63,2,0) -> 0 | Q63: =IF(O63+P63=4,5,0) -> 0 | S63: =IF(D63=F63,1,0) -> 1 | T63: =IF(H63=J63,1,0) -> 0 | U63: =IF(S63+T63=2,5,0) -> 0 | V63: =IF(Q63=5,0,U63) -> 0 | X63: =IF(D63>F63,1,0) -> 0 | Y63: =IF(H63>J63,1,0) -> 1 | Z63: =IF(X63+Y63=2,5,0) -> 0 | AA63: =IF(H63="n",0,Z63) -> 0 | AB63: =IF(Q63=5,0,AA63) -> 0 | AD63: =IF(D63<F63,1,0) -> 0 | AE63: =IF(H63<J63,1,0) -> 0 | AF63: =IF(AD63+AE63=2,5,0) -> 0 | AG63: =IF(Q63=5,0,AF63) -> 0
E65: x | H65: n | I65: x | J65: d | K65: =O65+P65+U65+AA65+AF65 -> 0 | O65: =IF(D65=H65,2,0) -> 0 | P65: =IF(F65=J65,2,0) -> 0 | Q65: =IF(O65+P65=4,5,0) -> 0 | S65: =IF(D65=F65,1,0) -> 1 | T65: =IF(H65=J65,1,0) -> 0 | U65: =IF(S65+T65=2,5,0) -> 0 | V65: =IF(Q65=5,0,U65) -> 0 | X65: =IF(D65>F65,1,0) -> 0 | Y65: =IF(H65>J65,1,0) -> 1 | Z65: =IF(X65+Y65=2,5,0) -> 0 | AA65: =IF(H65="n",0,Z65) -> 0 | AB65: =IF(Q65=5,0,AA65) -> 0 | AD65: =IF(D65<F65,1,0) -> 0 | AE65: =IF(H65<J65,1,0) -> 0 | AF65: =IF(AD65+AE65=2,5,0) -> 0 | AG65: =IF(Q65=5,0,AF65) -> 0
E67: x | H67: n | I67: x | J67: d | K67: =O67+P67+U67+AA67+AF67 -> 0 | O67: =IF(D67=H67,2,0) -> 0 | P67: =IF(F67=J67,2,0) -> 0 | Q67: =IF(O67+P67=4,5,0) -> 0 | S67: =IF(D67=F67,1,0) -> 1 | T67: =IF(H67=J67,1,0) -> 0 | U67: =IF(S67+T67=2,5,0) -> 0 | V67: =IF(Q67=5,0,U67) -> 0 | X67: =IF(D67>F67,1,0) -> 0 | Y67: =IF(H67>J67,1,0) -> 1 | Z67: =IF(X67+Y67=2,5,0) -> 0 | AA67: =IF(H67="n",0,Z67) -> 0 | AB67: =IF(Q67=5,0,AA67) -> 0 | AD67: =IF(D67<F67,1,0) -> 0 | AE67: =IF(H67<J67,1,0) -> 0 | AF67: =IF(AD67+AE67=2,5,0) -> 0 | AG67: =IF(Q67=5,0,AF67) -> 0
E70: x | H70: n | I70: x | J70: d | K70: =O70+P70+U70+AA70+AF70 -> 0 | L70: G | O70: =IF(D70=H70,2,0) -> 0 | P70: =IF(F70=J70,2,0) -> 0 | Q70: =IF(O70+P70=4,5,0) -> 0 | S70: =IF(D70=F70,1,0) -> 1 | T70: =IF(H70=J70,1,0) -> 0 | U70: =IF(S70+T70=2,5,0) -> 0 | V70: =IF(Q70=5,0,U70) -> 0 | X70: =IF(D70>F70,1,0) -> 0 | Y70: =IF(H70>J70,1,0) -> 1 | Z70: =IF(X70+Y70=2,5,0) -> 0 | AA70: =IF(H70="n",0,Z70) -> 0 | AB70: =IF(Q70=5,0,AA70) -> 0 | AD70: =IF(D70<F70,1,0) -> 0 | AE70: =IF(H70<J70,1,0) -> 0 | AF70: =IF(AD70+AE70=2,5,0) -> 0 | AG70: =IF(Q70=5,0,AF70) -> 0
...

Sheet T (3)
A1: Nome | C1: Ana Beatriz | S1: empate | X1: vitoria A | AD1: Vitiria B
O2: ok | P2: ok
D3: PARTICIPANTE | H3: OFICIAL | K3: PONTOS
A4: =TABELA!A4 -> 46201 | B4: =TABELA!B4 -> 0.66666667 | C4: =TABELA!C4 -> Africa do Sul | D4: 1 | E4: x | F4: 2 | G4: =TABELA!G4 -> Canadá | H4: =TABELA!D4 -> 0 | I4: x | J4: =TABELA!F4 -> 1 | K4: =O4+P4+U4+AA4+AF4 -> 5 | L4: a | O4: =IF(D4=H4,2,0) -> 0 | P4: =IF(F4=J4,2,0) -> 0 | Q4: =IF(O4+P4=4,5,0) -> 0 | S4: =IF(D4=F4,1,0) -> 0 | T4: =IF(H4=J4,1,0) -> 0 | U4: =IF(S4+T4=2,5,0) -> 0 | V4: =IF(Q4=5,0,U4) -> 0 | X4: =IF(D4>F4,1,0) -> 0 | Y4: =IF(H4>J4,1,0) -> 0 | Z4: =IF(X4+Y4=2,5,0) -> 0 | AA4: =IF(H4="n",0,Z4) -> 0 | AB4: =IF(Q4=5,0,AA4) -> 0 | AD4: =IF(D4<F4,1,0) -> 1 | AE4: =IF(H4<J4,1,0) -> 1 | AF4: =IF(AD4+AE4=2,5,0) -> 5 | AG4: =IF(Q4=5,0,AF4) -> 5
A5: =TABELA!A5 -> 46202 | B5: =TABELA!B5 -> 0.58333333 | C5: =TABELA!C5 -> Brasil | D5: 2 | E5: x | F5: 1 | G5: =TABELA!G5 -> Japão | H5: =TABELA!D5 -> 2 | I5: x | J5: =TABELA!F5 -> 1 | K5: =O5+P5+U5+AA5+AF5 -> 9 | O5: =IF(D5=H5,2,0) -> 2 | P5: =IF(F5=J5,2,0) -> 2 | Q5: =IF(O5+P5=4,5,0) -> 5 | S5: =IF(D5=F5,1,0) -> 0 | T5: =IF(H5=J5,1,0) -> 0 | U5: =IF(S5+T5=2,5,0) -> 0 | V5: =IF(Q5=5,0,U5) -> 0 | X5: =IF(D5>F5,1,0) -> 1 | Y5: =IF(H5>J5,1,0) -> 1 | Z5: =IF(X5+Y5=2,5,0) -> 5 | AA5: =IF(H5="n",0,Z5) -> 5 | AB5: =IF(Q5=5,0,AA5) -> 0 | AD5: =IF(D5<F5,1,0) -> 0 | AE5: =IF(H5<J5,1,0) -> 0 | AF5: =IF(AD5+AE5=2,5,0) -> 0 | AG5: =IF(Q5=5,0,AF5) -> 0
A6: =TABELA!A6 -> 46202 | B6: =TABELA!B6 -> 0.72916667 | C6: =TABELA!C6 -> Alemanha | D6: 2 | E6: x | F6: 0 | G6: =TABELA!G6 -> Paraguai | H6: =TABELA!D6 -> 1 | I6: x | J6: =TABELA!F6 -> 1 | K6: =O6+P6+U6+AA6+AF6 -> 0 | O6: =IF(D6=H6,2,0) -> 0 | P6: =IF(F6=J6,2,0) -> 0 | Q6: =IF(O6+P6=4,5,0) -> 0 | S6: =IF(D6=F6,1,0) -> 0 | T6: =IF(H6=J6,1,0) -> 1 | U6: =IF(S6+T6=2,5,0) -> 0 | V6: =IF(Q6=5,0,U6) -> 0 | X6: =IF(D6>F6,1,0) -> 1 | Y6: =IF(H6>J6,1,0) -> 0 | Z6: =IF(X6+Y6=2,5,0) -> 0 | AA6: =IF(H6="n",0,Z6) -> 0 | AB6: =IF(Q6=5,0,AA6) -> 0 | AD6: =IF(D6<F6,1,0) -> 0 | AE6: =IF(H6<J6,1,0) -> 0 | AF6: =IF(AD6+AE6=2,5,0) -> 0 | AG6: =IF(Q6=5,0,AF6) -> 0
A7: =TABELA!A7 -> 46202 | B7: =TABELA!B7 -> 0.91666667 | C7: =TABELA!C7 -> Holanda | D7: 1 | E7: x | F7: 1 | G7: =TABELA!G7 -> Marrocos | H7: =TABELA!D7 -> 1 | I7: x | J7: =TABELA!F7 -> 1 | K7: =O7+P7+U7+AA7+AF7 -> 9 | O7: =IF(D7=H7,2,0) -> 2 | P7: =IF(F7=J7,2,0) -> 2 | Q7: =IF(O7+P7=4,5,0) -> 5 | S7: =IF(D7=F7,1,0) -> 1 | T7: =IF(H7=J7,1,0) -> 1 | U7: =IF(S7+T7=2,5,0) -> 5 | V7: =IF(Q7=5,0,U7) -> 0 | X7: =IF(D7>F7,1,0) -> 0 | Y7: =IF(H7>J7,1,0) -> 0 | Z7: =IF(X7+Y7=2,5,0) -> 0 | AA7: =IF(H7="n",0,Z7) -> 0 | AB7: =IF(Q7=5,0,AA7) -> 0 | AD7: =IF(D7<F7,1,0) -> 0 | AE7: =IF(H7<J7,1,0) -> 0 | AF7: =IF(AD7+AE7=2,5,0) -> 0 | AG7: =IF(Q7=5,0,AF7) -> 0
A8: =TABELA!A8 -> 46203 | B8: =TABELA!B8 -> 0.58333333 | C8: =TABELA!C8 -> Cost. do Marf. | D8: 1 | E8: x | F8: 2 | G8: =TABELA!G8 -> Noruega | H8: =TABELA!D8 -> n | I8: x | J8: =TABELA!F8 -> d | K8: =O8+P8+U8+AA8+AF8 -> 0 | O8: =IF(D8=H8,2,0) -> 0 | P8: =IF(F8=J8,2,0) -> 0 | Q8: =IF(O8+P8=4,5,0) -> 0 | S8: =IF(D8=F8,1,0) -> 0 | T8: =IF(H8=J8,1,0) -> 0 | U8: =IF(S8+T8=2,5,0) -> 0 | V8: =IF(Q8=5,0,U8) -> 0 | X8: =IF(D8>F8,1,0) -> 0 | Y8: =IF(H8>J8,1,0) -> 1 | Z8: =IF(X8+Y8=2,5,0) -> 0 | AA8: =IF(H8="n",0,Z8) -> 0 | AB8: =IF(Q8=5,0,AA8) -> 0 | AD8: =IF(D8<F8,1,0) -> 1 | AE8: =IF(H8<J8,1,0) -> 0 | AF8: =IF(AD8+AE8=2,5,0) -> 0 | AG8: =IF(Q8=5,0,AF8) -> 0
A9: =TABELA!A9 -> 46203 | B9: =TABELA!B9 -> 0.75 | C9: =TABELA!C9 -> França | D9: 3 | E9: x | F9: 1 | G9: =TABELA!G9 -> Suécia | H9: =TABELA!D9 -> n | I9: x | J9: =TABELA!F9 -> d | K9: =O9+P9+U9+AA9+AF9 -> 0 | O9: =IF(D9=H9,2,0) -> 0 | P9: =IF(F9=J9,2,0) -> 0 | Q9: =IF(O9+P9=4,5,0) -> 0 | S9: =IF(D9=F9,1,0) -> 0 | T9: =IF(H9=J9,1,0) -> 0 | U9: =IF(S9+T9=2,5,0) -> 0 | V9: =IF(Q9=5,0,U9) -> 0 | X9: =IF(D9>F9,1,0) -> 1 | Y9: =IF(H9>J9,1,0) -> 1 | Z9: =IF(X9+Y9=2,5,0) -> 5 | AA9: =IF(H9="n",0,Z9) -> 0 | AB9: =IF(Q9=5,0,AA9) -> 0 | AD9: =IF(D9<F9,1,0) -> 0 | AE9: =IF(H9<J9,1,0) -> 0 | AF9: =IF(AD9+AE9=2,5,0) -> 0 | AG9: =IF(Q9=5,0,AF9) -> 0
A11: =TABELA!A11 -> 46203 | B11: =TABELA!B11 -> 0.91666667 | C11: =TABELA!C11 -> México | D11: 1 | E11: x | F11: 0 | G11: =TABELA!G11 -> Equador | H11: =TABELA!D11 -> n | I11: x | J11: =TABELA!F11 -> d | K11: =O11+P11+U11+AA11+AF11 -> 0 | L11: B | O11: =IF(D11=H11,2,0) -> 0 | P11: =IF(F11=J11,2,0) -> 0 | Q11: =IF(O11+P11=4,5,0) -> 0 | S11: =IF(D11=F11,1,0) -> 0 | T11: =IF(H11=J11,1,0) -> 0 | U11: =IF(S11+T11=2,5,0) -> 0 | V11: =IF(Q11=5,0,U11) -> 0 | X11: =IF(D11>F11,1,0) -> 1 | Y11: =IF(H11>J11,1,0) -> 1 | Z11: =IF(X11+Y11=2,5,0) -> 5 | AA11: =IF(H11="n",0,Z11) -> 0 | AB11: =IF(Q11=5,0,AA11) -> 0 | AD11: =IF(D11<F11,1,0) -> 0 | AE11: =IF(H11<J11,1,0) -> 0 | AF11: =IF(AD11+AE11=2,5,0) -> 0 | AG11: =IF(Q11=5,0,AF11) -> 0
A12: =TABELA!A12 -> 46204 | B12: =TABELA!B12 -> 0.54166667 | C12: =TABELA!C12 -> Inglaterra | D12: 2 | E12: x | F12: 0 | G12: =TABELA!G12 -> Congo | H12: =TABELA!D12 -> n | I12: x | J12: =TABELA!F12 -> d | K12: =O12+P12+U12+AA12+AF12 -> 0 | O12: =IF(D12=H12,2,0) -> 0 | P12: =IF(F12=J12,2,0) -> 0 | Q12: =IF(O12+P12=4,5,0) -> 0 | S12: =IF(D12=F12,1,0) -> 0 | T12: =IF(H12=J12,1,0) -> 0 | U12: =IF(S12+T12=2,5,0) -> 0 | V12: =IF(Q12=5,0,U12) -> 0 | X12: =IF(D12>F12,1,0) -> 1 | Y12: =IF(H12>J12,1,0) -> 1 | Z12: =IF(X12+Y12=2,5,0) -> 5 | AA12: =IF(H12="n",0,Z12) -> 0 | AB12: =IF(Q12=5,0,AA12) -> 0 | AD12: =IF(D12<F12,1,0) -> 0 | AE12: =IF(H12<J12,1,0) -> 0 | AF12: =IF(AD12+AE12=2,5,0) -> 0 | AG12: =IF(Q12=5,0,AF12) -> 0
A13: =TABELA!A13 -> 46204 | B13: =TABELA!B13 -> 0.70833333 | C13: =TABELA!C13 -> Bélgica | D13: 2 | E13: x | F13: 1 | G13: =TABELA!G13 -> Senegal | H13: =TABELA!D13 -> n | I13: x | J13: =TABELA!F13 -> d | K13: =O13+P13+U13+AA13+AF13 -> 0 | O13: =IF(D13=H13,2,0) -> 0 | P13: =IF(F13=J13,2,0) -> 0 | Q13: =IF(O13+P13=4,5,0) -> 0 | S13: =IF(D13=F13,1,0) -> 0 | T13: =IF(H13=J13,1,0) -> 0 | U13: =IF(S13+T13=2,5,0) -> 0 | V13: =IF(Q13=5,0,U13) -> 0 | X13: =IF(D13>F13,1,0) -> 1 | Y13: =IF(H13>J13,1,0) -> 1 | Z13: =IF(X13+Y13=2,5,0) -> 5 | AA13: =IF(H13="n",0,Z13) -> 0 | AB13: =IF(Q13=5,0,AA13) -> 0 | AD13: =IF(D13<F13,1,0) -> 0 | AE13: =IF(H13<J13,1,0) -> 0 | AF13: =IF(AD13+AE13=2,5,0) -> 0 | AG13: =IF(Q13=5,0,AF13) -> 0
A14: =TABELA!A14 -> 46204 | B14: =TABELA!B14 -> 0.875 | C14: =TABELA!C14 -> Estados Unidos | D14: 2 | E14: x | F14: 0 | G14: =TABELA!G14 -> Bósnia | H14: =TABELA!D14 -> n | I14: x | J14: =TABELA!F14 -> d | K14: =O14+P14+U14+AA14+AF14 -> 0 | O14: =IF(D14=H14,2,0) -> 0 | P14: =IF(F14=J14,2,0) -> 0 | Q14: =IF(O14+P14=4,5,0) -> 0 | S14: =IF(D14=F14,1,0) -> 0 | T14: =IF(H14=J14,1,0) -> 0 | U14: =IF(S14+T14=2,5,0) -> 0 | V14: =IF(Q14=5,0,U14) -> 0 | X14: =IF(D14>F14,1,0) -> 1 | Y14: =IF(H14>J14,1,0) -> 1 | Z14: =IF(X14+Y14=2,5,0) -> 5 | AA14: =IF(H14="n",0,Z14) -> 0 | AB14: =IF(Q14=5,0,AA14) -> 0 | AD14: =IF(D14<F14,1,0) -> 0 | AE14: =IF(H14<J14,1,0) -> 0 | AF14: =IF(AD14+AE14=2,5,0) -> 0 | AG14: =IF(Q14=5,0,AF14) -> 0
A15: =TABELA!A15 -> 46205 | B15: =TABELA!B15 -> 0.66666667 | C15: Espanha | D15: 2 | E15: x | F15: 1 | G15: =TABELA!G15 -> Áustria | H15: =TABELA!D15 -> n | I15: x | J15: =TABELA!F15 -> d | K15: =O15+P15+U15+AA15+AF15 -> 0 | O15: =IF(D15=H15,2,0) -> 0 | P15: =IF(F15=J15,2,0) -> 0 | Q15: =IF(O15+P15=4,5,0) -> 0 | S15: =IF(D15=F15,1,0) -> 0 | T15: =IF(H15=J15,1,0) -> 0 | U15: =IF(S15+T15=2,5,0) -> 0 | V15: =IF(Q15=5,0,U15) -> 0 | X15: =IF(D15>F15,1,0) -> 1 | Y15: =IF(H15>J15,1,0) -> 1 | Z15: =IF(X15+Y15=2,5,0) -> 5 | AA15: =IF(H15="n",0,Z15) -> 0 | AB15: =IF(Q15=5,0,AA15) -> 0 | AD15: =IF(D15<F15,1,0) -> 0 | AE15: =IF(H15<J15,1,0) -> 0 | AF15: =IF(AD15+AE15=2,5,0) -> 0 | AG15: =IF(Q15=5,0,AF15) -> 0
A16: =TABELA!A16 -> 46205 | B16: =TABELA!B16 -> 0.83333333 | C16: =TABELA!C16 -> Portugal | D16: 1 | E16: x | F16: 1 | G16: =TABELA!G16 -> Croácia | H16: =TABELA!D16 -> n | I16: x | J16: =TABELA!F16 -> d | K16: =O16+P16+U16+AA16+AF16 -> 0 | O16: =IF(D16=H16,2,0) -> 0 | P16: =IF(F16=J16,2,0) -> 0 | Q16: =IF(O16+P16=4,5,0) -> 0 | S16: =IF(D16=F16,1,0) -> 1 | T16: =IF(H16=J16,1,0) -> 0 | U16: =IF(S16+T16=2,5,0) -> 0 | V16: =IF(Q16=5,0,U16) -> 0 | X16: =IF(D16>F16,1,0) -> 0 | Y16: =IF(H16>J16,1,0) -> 1 | Z16: =IF(X16+Y16=2,5,0) -> 0 | AA16: =IF(H16="n",0,Z16) -> 0 | AB16: =IF(Q16=5,0,AA16) -> 0 | AD16: =IF(D16<F16,1,0) -> 0 | AE16: =IF(H16<J16,1,0) -> 0 | AF16: =IF(AD16+AE16=2,5,0) -> 0 | AG16: =IF(Q16=5,0,AF16) -> 0
